<robot name="">
    <link name="world"/>
    <!-- Joint & Link: trunk-B0L0 Branch Id:0 Level: 0, Child idx:0 )-->
<joint name="joint-world-trunk-B0L0" type="fixed">
        <parent link="world"/>
        <child link="link-trunk-B0L0"/>
        <origin xyz="0 0 0" rpy="0 0 0"/>
        </joint>
    <link name="link-trunk-B0L0">
        <visual>
            <geometry>
                <cylinder length="1.5" radius="0.08"/>
            </geometry>
            <origin xyz="0 0 0.75" rpy="0 0 0"/>
            <material name="brown">
                <color rgba="0.1 0.2 0.2 1"/>
            </material>
        </visual>
        <collision>
            <geometry>
                <cylinder length="1.5" radius="0.08"/>
            </geometry>
            <origin xyz="0 0 0.75" rpy="0 0 0"/>
        </collision>
        <inertial>
            <mass value="1.508"/>
            <inertia ixx="0" ixy="0" ixz="0" iyy="0" iyz="0" izz="0"/>
            <origin xyz="0 0 0.75" rpy="0 0 0"/>
        </inertial>
    </link>
<!-- Joint & Link: branch-B1L1P0 Branch Id:1 Level: 1, Child idx:0 )-->
<joint name="joint-trunk-B0L0-to-branch-B1L1P0" type="revolute">
        <parent link="link-trunk-B0L0"/>
        <child link="link-branch-B1L1P0"/>
        <origin xyz="0 0 1.49" rpy="-1.047 0.0 0"/>
        <axis xyz="-1 0 0"/>
        <limit lower="-0.349" upper="0.349"/>
        <dynamics damping="1.1" friction="0.0"/>
    </joint>
    <link name="link-branch-B1L1P0">
        <visual>
            <geometry>
                <cylinder length="0.8" radius="0.057"/>
            </geometry>
            <origin xyz="0 0 0.4" rpy="0 0 0"/>
            <material name="brown">
                <color rgba="0.1 0.2 0.2 1"/>
            </material>
        </visual>
        <collision>
            <geometry>
                <cylinder length="0.8" radius="0.057"/>
            </geometry>
            <origin xyz="0 0 0.4" rpy="0 0 0"/>
        </collision>
        <inertial>
            <mass value="0.408"/>
            <inertia ixx="0.022" ixy="0" ixz="0" iyy="0.022" iyz="0" izz="0.001"/>
            <origin xyz="0 0 0.4" rpy="0 0 0"/>
        </inertial>
    </link>
<!-- Joint & Link: branch-B22L1P0 Branch Id:22 Level: 1, Child idx:1 )-->
<joint name="joint-trunk-B0L0-to-branch-B22L1P0" type="revolute">
        <parent link="link-trunk-B0L0"/>
        <child link="link-branch-B22L1P0"/>
        <origin xyz="0 0 1.49" rpy="1.047 0.0 0"/>
        <axis xyz="1 0 0"/>
        <limit lower="-0.349" upper="0.349"/>
        <dynamics damping="1.1" friction="0.0"/>
    </joint>
    <link name="link-branch-B22L1P0">
        <visual>
            <geometry>
                <cylinder length="0.8" radius="0.057"/>
            </geometry>
            <origin xyz="0 0 0.4" rpy="0 0 0"/>
            <material name="brown">
                <color rgba="0.1 0.2 0.2 1"/>
            </material>
        </visual>
        <collision>
            <geometry>
                <cylinder length="0.8" radius="0.057"/>
            </geometry>
            <origin xyz="0 0 0.4" rpy="0 0 0"/>
        </collision>
        <inertial>
            <mass value="0.408"/>
            <inertia ixx="0.022" ixy="0" ixz="0" iyy="0.022" iyz="0" izz="0.001"/>
            <origin xyz="0 0 0.4" rpy="0 0 0"/>
        </inertial>
    </link>
<!-- Joint & Link: branch-B43L1P0 Branch Id:43 Level: 1, Child idx:2 )-->
<joint name="joint-trunk-B0L0-to-branch-B43L1P0" type="revolute">
        <parent link="link-trunk-B0L0"/>
        <child link="link-branch-B43L1P0"/>
        <origin xyz="0 0 1.49" rpy="0.0 -1.047 0"/>
        <axis xyz="0 -1 0"/>
        <limit lower="-0.349" upper="0.349"/>
        <dynamics damping="1.1" friction="0.0"/>
    </joint>
    <link name="link-branch-B43L1P0">
        <visual>
            <geometry>
                <cylinder length="0.8" radius="0.057"/>
            </geometry>
            <origin xyz="0 0 0.4" rpy="0 0 0"/>
            <material name="brown">
                <color rgba="0.1 0.2 0.2 1"/>
            </material>
        </visual>
        <collision>
            <geometry>
                <cylinder length="0.8" radius="0.057"/>
            </geometry>
            <origin xyz="0 0 0.4" rpy="0 0 0"/>
        </collision>
        <inertial>
            <mass value="0.408"/>
            <inertia ixx="0.022" ixy="0" ixz="0" iyy="0.022" iyz="0" izz="0.001"/>
            <origin xyz="0 0 0.4" rpy="0 0 0"/>
        </inertial>
    </link>
<!-- Joint & Link: branch-B64L1P0 Branch Id:64 Level: 1, Child idx:3 )-->
<joint name="joint-trunk-B0L0-to-branch-B64L1P0" type="revolute">
        <parent link="link-trunk-B0L0"/>
        <child link="link-branch-B64L1P0"/>
        <origin xyz="0 0 1.49" rpy="0.0 1.047 0"/>
        <axis xyz="0 1 0"/>
        <limit lower="-0.349" upper="0.349"/>
        <dynamics damping="1.1" friction="0.0"/>
    </joint>
    <link name="link-branch-B64L1P0">
        <visual>
            <geometry>
                <cylinder length="0.8" radius="0.057"/>
            </geometry>
            <origin xyz="0 0 0.4" rpy="0 0 0"/>
            <material name="brown">
                <color rgba="0.1 0.2 0.2 1"/>
            </material>
        </visual>
        <collision>
            <geometry>
                <cylinder length="0.8" radius="0.057"/>
            </geometry>
            <origin xyz="0 0 0.4" rpy="0 0 0"/>
        </collision>
        <inertial>
            <mass value="0.408"/>
            <inertia ixx="0.022" ixy="0" ixz="0" iyy="0.022" iyz="0" izz="0.001"/>
            <origin xyz="0 0 0.4" rpy="0 0 0"/>
        </inertial>
    </link>
<!-- Joint & Link: branch-B2L2P1 Branch Id:2 Level: 2, Child idx:0 )-->
<joint name="joint-branch-B1L1P0-to-branch-B2L2P1" type="revolute">
        <parent link="link-branch-B1L1P0"/>
        <child link="link-branch-B2L2P1"/>
        <origin xyz="0 0 0.79" rpy="-1.047 0.0 0"/>
        <axis xyz="-1 0 0"/>
        <limit lower="-0.349" upper="0.349"/>
        <dynamics damping="0.173" friction="0.0"/>
    </joint>
    <link name="link-branch-B2L2P1">
        <visual>
            <geometry>
                <cylinder length="0.64" radius="0.04"/>
            </geometry>
            <origin xyz="0 0 0.32" rpy="0 0 0"/>
            <material name="brown">
                <color rgba="0.1 0.2 0.2 1"/>
            </material>
        </visual>
        <collision>
            <geometry>
                <cylinder length="0.64" radius="0.04"/>
            </geometry>
            <origin xyz="0 0 0.32" rpy="0 0 0"/>
        </collision>
        <inertial>
            <mass value="0.161"/>
            <inertia ixx="0.006" ixy="0" ixz="0" iyy="0.006" iyz="0" izz="0.0"/>
            <origin xyz="0 0 0.32" rpy="0 0 0"/>
        </inertial>
    </link>
<!-- Joint & Link: branch-B7L2P1 Branch Id:7 Level: 2, Child idx:1 )-->
<joint name="joint-branch-B1L1P0-to-branch-B7L2P1" type="revolute">
        <parent link="link-branch-B1L1P0"/>
        <child link="link-branch-B7L2P1"/>
        <origin xyz="0 0 0.79" rpy="1.047 0.0 0"/>
        <axis xyz="1 0 0"/>
        <limit lower="-0.349" upper="0.349"/>
        <dynamics damping="0.173" friction="0.0"/>
    </joint>
    <link name="link-branch-B7L2P1">
        <visual>
            <geometry>
                <cylinder length="0.64" radius="0.04"/>
            </geometry>
            <origin xyz="0 0 0.32" rpy="0 0 0"/>
            <material name="brown">
                <color rgba="0.1 0.2 0.2 1"/>
            </material>
        </visual>
        <collision>
            <geometry>
                <cylinder length="0.64" radius="0.04"/>
            </geometry>
            <origin xyz="0 0 0.32" rpy="0 0 0"/>
        </collision>
        <inertial>
            <mass value="0.161"/>
            <inertia ixx="0.006" ixy="0" ixz="0" iyy="0.006" iyz="0" izz="0.0"/>
            <origin xyz="0 0 0.32" rpy="0 0 0"/>
        </inertial>
    </link>
<!-- Joint & Link: branch-B12L2P1 Branch Id:12 Level: 2, Child idx:2 )-->
<joint name="joint-branch-B1L1P0-to-branch-B12L2P1" type="revolute">
        <parent link="link-branch-B1L1P0"/>
        <child link="link-branch-B12L2P1"/>
        <origin xyz="0 0 0.79" rpy="0.0 -1.047 0"/>
        <axis xyz="0 -1 0"/>
        <limit lower="-0.349" upper="0.349"/>
        <dynamics damping="0.173" friction="0.0"/>
    </joint>
    <link name="link-branch-B12L2P1">
        <visual>
            <geometry>
                <cylinder length="0.64" radius="0.04"/>
            </geometry>
            <origin xyz="0 0 0.32" rpy="0 0 0"/>
            <material name="brown">
                <color rgba="0.1 0.2 0.2 1"/>
            </material>
        </visual>
        <collision>
            <geometry>
                <cylinder length="0.64" radius="0.04"/>
            </geometry>
            <origin xyz="0 0 0.32" rpy="0 0 0"/>
        </collision>
        <inertial>
            <mass value="0.161"/>
            <inertia ixx="0.006" ixy="0" ixz="0" iyy="0.006" iyz="0" izz="0.0"/>
            <origin xyz="0 0 0.32" rpy="0 0 0"/>
        </inertial>
    </link>
<!-- Joint & Link: branch-B17L2P1 Branch Id:17 Level: 2, Child idx:3 )-->
<joint name="joint-branch-B1L1P0-to-branch-B17L2P1" type="revolute">
        <parent link="link-branch-B1L1P0"/>
        <child link="link-branch-B17L2P1"/>
        <origin xyz="0 0 0.79" rpy="0.0 1.047 0"/>
        <axis xyz="0 1 0"/>
        <limit lower="-0.349" upper="0.349"/>
        <dynamics damping="0.173" friction="0.0"/>
    </joint>
    <link name="link-branch-B17L2P1">
        <visual>
            <geometry>
                <cylinder length="0.64" radius="0.04"/>
            </geometry>
            <origin xyz="0 0 0.32" rpy="0 0 0"/>
            <material name="brown">
                <color rgba="0.1 0.2 0.2 1"/>
            </material>
        </visual>
        <collision>
            <geometry>
                <cylinder length="0.64" radius="0.04"/>
            </geometry>
            <origin xyz="0 0 0.32" rpy="0 0 0"/>
        </collision>
        <inertial>
            <mass value="0.161"/>
            <inertia ixx="0.006" ixy="0" ixz="0" iyy="0.006" iyz="0" izz="0.0"/>
            <origin xyz="0 0 0.32" rpy="0 0 0"/>
        </inertial>
    </link>
<!-- Joint & Link: branch-B23L2P22 Branch Id:23 Level: 2, Child idx:0 )-->
<joint name="joint-branch-B22L1P0-to-branch-B23L2P22" type="revolute">
        <parent link="link-branch-B22L1P0"/>
        <child link="link-branch-B23L2P22"/>
        <origin xyz="0 0 0.79" rpy="-1.047 0.0 0"/>
        <axis xyz="-1 0 0"/>
        <limit lower="-0.349" upper="0.349"/>
        <dynamics damping="0.173" friction="0.0"/>
    </joint>
    <link name="link-branch-B23L2P22">
        <visual>
            <geometry>
                <cylinder length="0.64" radius="0.04"/>
            </geometry>
            <origin xyz="0 0 0.32" rpy="0 0 0"/>
            <material name="brown">
                <color rgba="0.1 0.2 0.2 1"/>
            </material>
        </visual>
        <collision>
            <geometry>
                <cylinder length="0.64" radius="0.04"/>
            </geometry>
            <origin xyz="0 0 0.32" rpy="0 0 0"/>
        </collision>
        <inertial>
            <mass value="0.161"/>
            <inertia ixx="0.006" ixy="0" ixz="0" iyy="0.006" iyz="0" izz="0.0"/>
            <origin xyz="0 0 0.32" rpy="0 0 0"/>
        </inertial>
    </link>
<!-- Joint & Link: branch-B28L2P22 Branch Id:28 Level: 2, Child idx:1 )-->
<joint name="joint-branch-B22L1P0-to-branch-B28L2P22" type="revolute">
        <parent link="link-branch-B22L1P0"/>
        <child link="link-branch-B28L2P22"/>
        <origin xyz="0 0 0.79" rpy="1.047 0.0 0"/>
        <axis xyz="1 0 0"/>
        <limit lower="-0.349" upper="0.349"/>
        <dynamics damping="0.173" friction="0.0"/>
    </joint>
    <link name="link-branch-B28L2P22">
        <visual>
            <geometry>
                <cylinder length="0.64" radius="0.04"/>
            </geometry>
            <origin xyz="0 0 0.32" rpy="0 0 0"/>
            <material name="brown">
                <color rgba="0.1 0.2 0.2 1"/>
            </material>
        </visual>
        <collision>
            <geometry>
                <cylinder length="0.64" radius="0.04"/>
            </geometry>
            <origin xyz="0 0 0.32" rpy="0 0 0"/>
        </collision>
        <inertial>
            <mass value="0.161"/>
            <inertia ixx="0.006" ixy="0" ixz="0" iyy="0.006" iyz="0" izz="0.0"/>
            <origin xyz="0 0 0.32" rpy="0 0 0"/>
        </inertial>
    </link>
<!-- Joint & Link: branch-B33L2P22 Branch Id:33 Level: 2, Child idx:2 )-->
<joint name="joint-branch-B22L1P0-to-branch-B33L2P22" type="revolute">
        <parent link="link-branch-B22L1P0"/>
        <child link="link-branch-B33L2P22"/>
        <origin xyz="0 0 0.79" rpy="0.0 -1.047 0"/>
        <axis xyz="0 -1 0"/>
        <limit lower="-0.349" upper="0.349"/>
        <dynamics damping="0.173" friction="0.0"/>
    </joint>
    <link name="link-branch-B33L2P22">
        <visual>
            <geometry>
                <cylinder length="0.64" radius="0.04"/>
            </geometry>
            <origin xyz="0 0 0.32" rpy="0 0 0"/>
            <material name="brown">
                <color rgba="0.1 0.2 0.2 1"/>
            </material>
        </visual>
        <collision>
            <geometry>
                <cylinder length="0.64" radius="0.04"/>
            </geometry>
            <origin xyz="0 0 0.32" rpy="0 0 0"/>
        </collision>
        <inertial>
            <mass value="0.161"/>
            <inertia ixx="0.006" ixy="0" ixz="0" iyy="0.006" iyz="0" izz="0.0"/>
            <origin xyz="0 0 0.32" rpy="0 0 0"/>
        </inertial>
    </link>
<!-- Joint & Link: branch-B38L2P22 Branch Id:38 Level: 2, Child idx:3 )-->
<joint name="joint-branch-B22L1P0-to-branch-B38L2P22" type="revolute">
        <parent link="link-branch-B22L1P0"/>
        <child link="link-branch-B38L2P22"/>
        <origin xyz="0 0 0.79" rpy="0.0 1.047 0"/>
        <axis xyz="0 1 0"/>
        <limit lower="-0.349" upper="0.349"/>
        <dynamics damping="0.173" friction="0.0"/>
    </joint>
    <link name="link-branch-B38L2P22">
        <visual>
            <geometry>
                <cylinder length="0.64" radius="0.04"/>
            </geometry>
            <origin xyz="0 0 0.32" rpy="0 0 0"/>
            <material name="brown">
                <color rgba="0.1 0.2 0.2 1"/>
            </material>
        </visual>
        <collision>
            <geometry>
                <cylinder length="0.64" radius="0.04"/>
            </geometry>
            <origin xyz="0 0 0.32" rpy="0 0 0"/>
        </collision>
        <inertial>
            <mass value="0.161"/>
            <inertia ixx="0.006" ixy="0" ixz="0" iyy="0.006" iyz="0" izz="0.0"/>
            <origin xyz="0 0 0.32" rpy="0 0 0"/>
        </inertial>
    </link>
<!-- Joint & Link: branch-B44L2P43 Branch Id:44 Level: 2, Child idx:0 )-->
<joint name="joint-branch-B43L1P0-to-branch-B44L2P43" type="revolute">
        <parent link="link-branch-B43L1P0"/>
        <child link="link-branch-B44L2P43"/>
        <origin xyz="0 0 0.79" rpy="-1.047 0.0 0"/>
        <axis xyz="-1 0 0"/>
        <limit lower="-0.349" upper="0.349"/>
        <dynamics damping="0.173" friction="0.0"/>
    </joint>
    <link name="link-branch-B44L2P43">
        <visual>
            <geometry>
                <cylinder length="0.64" radius="0.04"/>
            </geometry>
            <origin xyz="0 0 0.32" rpy="0 0 0"/>
            <material name="brown">
                <color rgba="0.1 0.2 0.2 1"/>
            </material>
        </visual>
        <collision>
            <geometry>
                <cylinder length="0.64" radius="0.04"/>
            </geometry>
            <origin xyz="0 0 0.32" rpy="0 0 0"/>
        </collision>
        <inertial>
            <mass value="0.161"/>
            <inertia ixx="0.006" ixy="0" ixz="0" iyy="0.006" iyz="0" izz="0.0"/>
            <origin xyz="0 0 0.32" rpy="0 0 0"/>
        </inertial>
    </link>
<!-- Joint & Link: branch-B49L2P43 Branch Id:49 Level: 2, Child idx:1 )-->
<joint name="joint-branch-B43L1P0-to-branch-B49L2P43" type="revolute">
        <parent link="link-branch-B43L1P0"/>
        <child link="link-branch-B49L2P43"/>
        <origin xyz="0 0 0.79" rpy="1.047 0.0 0"/>
        <axis xyz="1 0 0"/>
        <limit lower="-0.349" upper="0.349"/>
        <dynamics damping="0.173" friction="0.0"/>
    </joint>
    <link name="link-branch-B49L2P43">
        <visual>
            <geometry>
                <cylinder length="0.64" radius="0.04"/>
            </geometry>
            <origin xyz="0 0 0.32" rpy="0 0 0"/>
            <material name="brown">
                <color rgba="0.1 0.2 0.2 1"/>
            </material>
        </visual>
        <collision>
            <geometry>
                <cylinder length="0.64" radius="0.04"/>
            </geometry>
            <origin xyz="0 0 0.32" rpy="0 0 0"/>
        </collision>
        <inertial>
            <mass value="0.161"/>
            <inertia ixx="0.006" ixy="0" ixz="0" iyy="0.006" iyz="0" izz="0.0"/>
            <origin xyz="0 0 0.32" rpy="0 0 0"/>
        </inertial>
    </link>
<!-- Joint & Link: branch-B54L2P43 Branch Id:54 Level: 2, Child idx:2 )-->
<joint name="joint-branch-B43L1P0-to-branch-B54L2P43" type="revolute">
        <parent link="link-branch-B43L1P0"/>
        <child link="link-branch-B54L2P43"/>
        <origin xyz="0 0 0.79" rpy="0.0 -1.047 0"/>
        <axis xyz="0 -1 0"/>
        <limit lower="-0.349" upper="0.349"/>
        <dynamics damping="0.173" friction="0.0"/>
    </joint>
    <link name="link-branch-B54L2P43">
        <visual>
            <geometry>
                <cylinder length="0.64" radius="0.04"/>
            </geometry>
            <origin xyz="0 0 0.32" rpy="0 0 0"/>
            <material name="brown">
                <color rgba="0.1 0.2 0.2 1"/>
            </material>
        </visual>
        <collision>
            <geometry>
                <cylinder length="0.64" radius="0.04"/>
            </geometry>
            <origin xyz="0 0 0.32" rpy="0 0 0"/>
        </collision>
        <inertial>
            <mass value="0.161"/>
            <inertia ixx="0.006" ixy="0" ixz="0" iyy="0.006" iyz="0" izz="0.0"/>
            <origin xyz="0 0 0.32" rpy="0 0 0"/>
        </inertial>
    </link>
<!-- Joint & Link: branch-B59L2P43 Branch Id:59 Level: 2, Child idx:3 )-->
<joint name="joint-branch-B43L1P0-to-branch-B59L2P43" type="revolute">
        <parent link="link-branch-B43L1P0"/>
        <child link="link-branch-B59L2P43"/>
        <origin xyz="0 0 0.79" rpy="0.0 1.047 0"/>
        <axis xyz="0 1 0"/>
        <limit lower="-0.349" upper="0.349"/>
        <dynamics damping="0.173" friction="0.0"/>
    </joint>
    <link name="link-branch-B59L2P43">
        <visual>
            <geometry>
                <cylinder length="0.64" radius="0.04"/>
            </geometry>
            <origin xyz="0 0 0.32" rpy="0 0 0"/>
            <material name="brown">
                <color rgba="0.1 0.2 0.2 1"/>
            </material>
        </visual>
        <collision>
            <geometry>
                <cylinder length="0.64" radius="0.04"/>
            </geometry>
            <origin xyz="0 0 0.32" rpy="0 0 0"/>
        </collision>
        <inertial>
            <mass value="0.161"/>
            <inertia ixx="0.006" ixy="0" ixz="0" iyy="0.006" iyz="0" izz="0.0"/>
            <origin xyz="0 0 0.32" rpy="0 0 0"/>
        </inertial>
    </link>
<!-- Joint & Link: branch-B65L2P64 Branch Id:65 Level: 2, Child idx:0 )-->
<joint name="joint-branch-B64L1P0-to-branch-B65L2P64" type="revolute">
        <parent link="link-branch-B64L1P0"/>
        <child link="link-branch-B65L2P64"/>
        <origin xyz="0 0 0.79" rpy="-1.047 0.0 0"/>
        <axis xyz="-1 0 0"/>
        <limit lower="-0.349" upper="0.349"/>
        <dynamics damping="0.173" friction="0.0"/>
    </joint>
    <link name="link-branch-B65L2P64">
        <visual>
            <geometry>
                <cylinder length="0.64" radius="0.04"/>
            </geometry>
            <origin xyz="0 0 0.32" rpy="0 0 0"/>
            <material name="brown">
                <color rgba="0.1 0.2 0.2 1"/>
            </material>
        </visual>
        <collision>
            <geometry>
                <cylinder length="0.64" radius="0.04"/>
            </geometry>
            <origin xyz="0 0 0.32" rpy="0 0 0"/>
        </collision>
        <inertial>
            <mass value="0.161"/>
            <inertia ixx="0.006" ixy="0" ixz="0" iyy="0.006" iyz="0" izz="0.0"/>
            <origin xyz="0 0 0.32" rpy="0 0 0"/>
        </inertial>
    </link>
<!-- Joint & Link: branch-B70L2P64 Branch Id:70 Level: 2, Child idx:1 )-->
<joint name="joint-branch-B64L1P0-to-branch-B70L2P64" type="revolute">
        <parent link="link-branch-B64L1P0"/>
        <child link="link-branch-B70L2P64"/>
        <origin xyz="0 0 0.79" rpy="1.047 0.0 0"/>
        <axis xyz="1 0 0"/>
        <limit lower="-0.349" upper="0.349"/>
        <dynamics damping="0.173" friction="0.0"/>
    </joint>
    <link name="link-branch-B70L2P64">
        <visual>
            <geometry>
                <cylinder length="0.64" radius="0.04"/>
            </geometry>
            <origin xyz="0 0 0.32" rpy="0 0 0"/>
            <material name="brown">
                <color rgba="0.1 0.2 0.2 1"/>
            </material>
        </visual>
        <collision>
            <geometry>
                <cylinder length="0.64" radius="0.04"/>
            </geometry>
            <origin xyz="0 0 0.32" rpy="0 0 0"/>
        </collision>
        <inertial>
            <mass value="0.161"/>
            <inertia ixx="0.006" ixy="0" ixz="0" iyy="0.006" iyz="0" izz="0.0"/>
            <origin xyz="0 0 0.32" rpy="0 0 0"/>
        </inertial>
    </link>
<!-- Joint & Link: branch-B75L2P64 Branch Id:75 Level: 2, Child idx:2 )-->
<joint name="joint-branch-B64L1P0-to-branch-B75L2P64" type="revolute">
        <parent link="link-branch-B64L1P0"/>
        <child link="link-branch-B75L2P64"/>
        <origin xyz="0 0 0.79" rpy="0.0 -1.047 0"/>
        <axis xyz="0 -1 0"/>
        <limit lower="-0.349" upper="0.349"/>
        <dynamics damping="0.173" friction="0.0"/>
    </joint>
    <link name="link-branch-B75L2P64">
        <visual>
            <geometry>
                <cylinder length="0.64" radius="0.04"/>
            </geometry>
            <origin xyz="0 0 0.32" rpy="0 0 0"/>
            <material name="brown">
                <color rgba="0.1 0.2 0.2 1"/>
            </material>
        </visual>
        <collision>
            <geometry>
                <cylinder length="0.64" radius="0.04"/>
            </geometry>
            <origin xyz="0 0 0.32" rpy="0 0 0"/>
        </collision>
        <inertial>
            <mass value="0.161"/>
            <inertia ixx="0.006" ixy="0" ixz="0" iyy="0.006" iyz="0" izz="0.0"/>
            <origin xyz="0 0 0.32" rpy="0 0 0"/>
        </inertial>
    </link>
<!-- Joint & Link: branch-B80L2P64 Branch Id:80 Level: 2, Child idx:3 )-->
<joint name="joint-branch-B64L1P0-to-branch-B80L2P64" type="revolute">
        <parent link="link-branch-B64L1P0"/>
        <child link="link-branch-B80L2P64"/>
        <origin xyz="0 0 0.79" rpy="0.0 1.047 0"/>
        <axis xyz="0 1 0"/>
        <limit lower="-0.349" upper="0.349"/>
        <dynamics damping="0.173" friction="0.0"/>
    </joint>
    <link name="link-branch-B80L2P64">
        <visual>
            <geometry>
                <cylinder length="0.64" radius="0.04"/>
            </geometry>
            <origin xyz="0 0 0.32" rpy="0 0 0"/>
            <material name="red">
                <color rgba="1 0.1 0.2 1"/>
            </material>
        </visual>
        <collision>
            <geometry>
                <cylinder length="0.64" radius="0.04"/>
            </geometry>
            <origin xyz="0 0 0.32" rpy="0 0 0"/>
        </collision>
        <inertial>
            <mass value="0.161"/>
            <inertia ixx="0.006" ixy="0" ixz="0" iyy="0.006" iyz="0" izz="0.0"/>
            <origin xyz="0 0 0.32" rpy="0 0 0"/>
        </inertial>
    </link>
<!-- Joint & Link: branch-B3L3P2 Branch Id:3 Level: 3, Child idx:0 )-->
<joint name="joint-branch-B2L2P1-to-branch-B3L3P2" type="revolute">
        <parent link="link-branch-B2L2P1"/>
        <child link="link-branch-B3L3P2"/>
        <origin xyz="0 0 0.63" rpy="-1.047 0.0 0"/>
        <axis xyz="-1 0 0"/>
        <limit lower="-0.349" upper="0.349"/>
        <dynamics damping="0.003" friction="0.0"/>
    </joint>
    <link name="link-branch-B3L3P2">
        <visual>
            <geometry>
                <cylinder length="0.026" radius="0.028"/>
            </geometry>
            <origin xyz="0 0 0.013" rpy="0 0 0"/>
            <material name="green">
                <color rgba="0.1 1 0.2 1"/>
            </material>
        </visual>
        <collision>
            <geometry>
                <cylinder length="0.026" radius="0.028"/>
            </geometry>
            <origin xyz="0 0 0.013" rpy="0 0 0"/>
        </collision>
        <inertial>
            <mass value="0.003"/>
            <inertia ixx="0.0" ixy="0" ixz="0" iyy="0.0" iyz="0" izz="0.0"/>
            <origin xyz="0 0 0.013" rpy="0 0 0"/>
        </inertial>
    </link>
<!-- Joint & Link: branch-B4L3P2 Branch Id:4 Level: 3, Child idx:1 )-->
<joint name="joint-branch-B2L2P1-to-branch-B4L3P2" type="revolute">
        <parent link="link-branch-B2L2P1"/>
        <child link="link-branch-B4L3P2"/>
        <origin xyz="0 0 0.63" rpy="1.047 0.0 0"/>
        <axis xyz="1 0 0"/>
        <limit lower="-0.349" upper="0.349"/>
        <dynamics damping="0.003" friction="0.0"/>
    </joint>
    <link name="link-branch-B4L3P2">
        <visual>
            <geometry>
                <cylinder length="0.026" radius="0.028"/>
            </geometry>
            <origin xyz="0 0 0.013" rpy="0 0 0"/>
            <material name="green">
                <color rgba="0.1 1 0.2 1"/>
            </material>
        </visual>
        <collision>
            <geometry>
                <cylinder length="0.026" radius="0.028"/>
            </geometry>
            <origin xyz="0 0 0.013" rpy="0 0 0"/>
        </collision>
        <inertial>
            <mass value="0.003"/>
            <inertia ixx="0.0" ixy="0" ixz="0" iyy="0.0" iyz="0" izz="0.0"/>
            <origin xyz="0 0 0.013" rpy="0 0 0"/>
        </inertial>
    </link>
<!-- Joint & Link: branch-B5L3P2 Branch Id:5 Level: 3, Child idx:2 )-->
<joint name="joint-branch-B2L2P1-to-branch-B5L3P2" type="revolute">
        <parent link="link-branch-B2L2P1"/>
        <child link="link-branch-B5L3P2"/>
        <origin xyz="0 0 0.63" rpy="0.0 -1.047 0"/>
        <axis xyz="0 -1 0"/>
        <limit lower="-0.349" upper="0.349"/>
        <dynamics damping="0.003" friction="0.0"/>
    </joint>
    <link name="link-branch-B5L3P2">
        <visual>
            <geometry>
                <cylinder length="0.026" radius="0.028"/>
            </geometry>
            <origin xyz="0 0 0.013" rpy="0 0 0"/>
            <material name="green">
                <color rgba="0.1 1 0.2 1"/>
            </material>
        </visual>
        <collision>
            <geometry>
                <cylinder length="0.026" radius="0.028"/>
            </geometry>
            <origin xyz="0 0 0.013" rpy="0 0 0"/>
        </collision>
        <inertial>
            <mass value="0.003"/>
            <inertia ixx="0.0" ixy="0" ixz="0" iyy="0.0" iyz="0" izz="0.0"/>
            <origin xyz="0 0 0.013" rpy="0 0 0"/>
        </inertial>
    </link>
<!-- Joint & Link: branch-B6L3P2 Branch Id:6 Level: 3, Child idx:3 )-->
<joint name="joint-branch-B2L2P1-to-branch-B6L3P2" type="revolute">
        <parent link="link-branch-B2L2P1"/>
        <child link="link-branch-B6L3P2"/>
        <origin xyz="0 0 0.63" rpy="0.0 1.047 0"/>
        <axis xyz="0 1 0"/>
        <limit lower="-0.349" upper="0.349"/>
        <dynamics damping="0.003" friction="0.0"/>
    </joint>
    <link name="link-branch-B6L3P2">
        <visual>
            <geometry>
                <cylinder length="0.026" radius="0.028"/>
            </geometry>
            <origin xyz="0 0 0.013" rpy="0 0 0"/>
            <material name="green">
                <color rgba="0.1 1 0.2 1"/>
            </material>
        </visual>
        <collision>
            <geometry>
                <cylinder length="0.026" radius="0.028"/>
            </geometry>
            <origin xyz="0 0 0.013" rpy="0 0 0"/>
        </collision>
        <inertial>
            <mass value="0.003"/>
            <inertia ixx="0.0" ixy="0" ixz="0" iyy="0.0" iyz="0" izz="0.0"/>
            <origin xyz="0 0 0.013" rpy="0 0 0"/>
        </inertial>
    </link>
<!-- Joint & Link: branch-B8L3P7 Branch Id:8 Level: 3, Child idx:0 )-->
<joint name="joint-branch-B7L2P1-to-branch-B8L3P7" type="revolute">
        <parent link="link-branch-B7L2P1"/>
        <child link="link-branch-B8L3P7"/>
        <origin xyz="0 0 0.63" rpy="-1.047 0.0 0"/>
        <axis xyz="-1 0 0"/>
        <limit lower="-0.349" upper="0.349"/>
        <dynamics damping="0.003" friction="0.0"/>
    </joint>
    <link name="link-branch-B8L3P7">
        <visual>
            <geometry>
                <cylinder length="0.026" radius="0.028"/>
            </geometry>
            <origin xyz="0 0 0.013" rpy="0 0 0"/>
            <material name="green">
                <color rgba="0.1 1 0.2 1"/>
            </material>
        </visual>
        <collision>
            <geometry>
                <cylinder length="0.026" radius="0.028"/>
            </geometry>
            <origin xyz="0 0 0.013" rpy="0 0 0"/>
        </collision>
        <inertial>
            <mass value="0.003"/>
            <inertia ixx="0.0" ixy="0" ixz="0" iyy="0.0" iyz="0" izz="0.0"/>
            <origin xyz="0 0 0.013" rpy="0 0 0"/>
        </inertial>
    </link>
<!-- Joint & Link: branch-B9L3P7 Branch Id:9 Level: 3, Child idx:1 )-->
<joint name="joint-branch-B7L2P1-to-branch-B9L3P7" type="revolute">
        <parent link="link-branch-B7L2P1"/>
        <child link="link-branch-B9L3P7"/>
        <origin xyz="0 0 0.63" rpy="1.047 0.0 0"/>
        <axis xyz="1 0 0"/>
        <limit lower="-0.349" upper="0.349"/>
        <dynamics damping="0.003" friction="0.0"/>
    </joint>
    <link name="link-branch-B9L3P7">
        <visual>
            <geometry>
                <cylinder length="0.026" radius="0.028"/>
            </geometry>
            <origin xyz="0 0 0.013" rpy="0 0 0"/>
            <material name="green">
                <color rgba="0.1 1 0.2 1"/>
            </material>
        </visual>
        <collision>
            <geometry>
                <cylinder length="0.026" radius="0.028"/>
            </geometry>
            <origin xyz="0 0 0.013" rpy="0 0 0"/>
        </collision>
        <inertial>
            <mass value="0.003"/>
            <inertia ixx="0.0" ixy="0" ixz="0" iyy="0.0" iyz="0" izz="0.0"/>
            <origin xyz="0 0 0.013" rpy="0 0 0"/>
        </inertial>
    </link>
<!-- Joint & Link: branch-B10L3P7 Branch Id:10 Level: 3, Child idx:2 )-->
<joint name="joint-branch-B7L2P1-to-branch-B10L3P7" type="revolute">
        <parent link="link-branch-B7L2P1"/>
        <child link="link-branch-B10L3P7"/>
        <origin xyz="0 0 0.63" rpy="0.0 -1.047 0"/>
        <axis xyz="0 -1 0"/>
        <limit lower="-0.349" upper="0.349"/>
        <dynamics damping="0.003" friction="0.0"/>
    </joint>
    <link name="link-branch-B10L3P7">
        <visual>
            <geometry>
                <cylinder length="0.026" radius="0.028"/>
            </geometry>
            <origin xyz="0 0 0.013" rpy="0 0 0"/>
            <material name="green">
                <color rgba="0.1 1 0.2 1"/>
            </material>
        </visual>
        <collision>
            <geometry>
                <cylinder length="0.026" radius="0.028"/>
            </geometry>
            <origin xyz="0 0 0.013" rpy="0 0 0"/>
        </collision>
        <inertial>
            <mass value="0.003"/>
            <inertia ixx="0.0" ixy="0" ixz="0" iyy="0.0" iyz="0" izz="0.0"/>
            <origin xyz="0 0 0.013" rpy="0 0 0"/>
        </inertial>
    </link>
<!-- Joint & Link: branch-B11L3P7 Branch Id:11 Level: 3, Child idx:3 )-->
<joint name="joint-branch-B7L2P1-to-branch-B11L3P7" type="revolute">
        <parent link="link-branch-B7L2P1"/>
        <child link="link-branch-B11L3P7"/>
        <origin xyz="0 0 0.63" rpy="0.0 1.047 0"/>
        <axis xyz="0 1 0"/>
        <limit lower="-0.349" upper="0.349"/>
        <dynamics damping="0.003" friction="0.0"/>
    </joint>
    <link name="link-branch-B11L3P7">
        <visual>
            <geometry>
                <cylinder length="0.026" radius="0.028"/>
            </geometry>
            <origin xyz="0 0 0.013" rpy="0 0 0"/>
            <material name="green">
                <color rgba="0.1 1 0.2 1"/>
            </material>
        </visual>
        <collision>
            <geometry>
                <cylinder length="0.026" radius="0.028"/>
            </geometry>
            <origin xyz="0 0 0.013" rpy="0 0 0"/>
        </collision>
        <inertial>
            <mass value="0.003"/>
            <inertia ixx="0.0" ixy="0" ixz="0" iyy="0.0" iyz="0" izz="0.0"/>
            <origin xyz="0 0 0.013" rpy="0 0 0"/>
        </inertial>
    </link>
<!-- Joint & Link: branch-B13L3P12 Branch Id:13 Level: 3, Child idx:0 )-->
<joint name="joint-branch-B12L2P1-to-branch-B13L3P12" type="revolute">
        <parent link="link-branch-B12L2P1"/>
        <child link="link-branch-B13L3P12"/>
        <origin xyz="0 0 0.63" rpy="-1.047 0.0 0"/>
        <axis xyz="-1 0 0"/>
        <limit lower="-0.349" upper="0.349"/>
        <dynamics damping="0.003" friction="0.0"/>
    </joint>
    <link name="link-branch-B13L3P12">
        <visual>
            <geometry>
                <cylinder length="0.026" radius="0.028"/>
            </geometry>
            <origin xyz="0 0 0.013" rpy="0 0 0"/>
            <material name="green">
                <color rgba="0.1 1 0.2 1"/>
            </material>
        </visual>
        <collision>
            <geometry>
                <cylinder length="0.026" radius="0.028"/>
            </geometry>
            <origin xyz="0 0 0.013" rpy="0 0 0"/>
        </collision>
        <inertial>
            <mass value="0.003"/>
            <inertia ixx="0.0" ixy="0" ixz="0" iyy="0.0" iyz="0" izz="0.0"/>
            <origin xyz="0 0 0.013" rpy="0 0 0"/>
        </inertial>
    </link>
<!-- Joint & Link: branch-B14L3P12 Branch Id:14 Level: 3, Child idx:1 )-->
<joint name="joint-branch-B12L2P1-to-branch-B14L3P12" type="revolute">
        <parent link="link-branch-B12L2P1"/>
        <child link="link-branch-B14L3P12"/>
        <origin xyz="0 0 0.63" rpy="1.047 0.0 0"/>
        <axis xyz="1 0 0"/>
        <limit lower="-0.349" upper="0.349"/>
        <dynamics damping="0.003" friction="0.0"/>
    </joint>
    <link name="link-branch-B14L3P12">
        <visual>
            <geometry>
                <cylinder length="0.026" radius="0.028"/>
            </geometry>
            <origin xyz="0 0 0.013" rpy="0 0 0"/>
            <material name="green">
                <color rgba="0.1 1 0.2 1"/>
            </material>
        </visual>
        <collision>
            <geometry>
                <cylinder length="0.026" radius="0.028"/>
            </geometry>
            <origin xyz="0 0 0.013" rpy="0 0 0"/>
        </collision>
        <inertial>
            <mass value="0.003"/>
            <inertia ixx="0.0" ixy="0" ixz="0" iyy="0.0" iyz="0" izz="0.0"/>
            <origin xyz="0 0 0.013" rpy="0 0 0"/>
        </inertial>
    </link>
<!-- Joint & Link: branch-B15L3P12 Branch Id:15 Level: 3, Child idx:2 )-->
<joint name="joint-branch-B12L2P1-to-branch-B15L3P12" type="revolute">
        <parent link="link-branch-B12L2P1"/>
        <child link="link-branch-B15L3P12"/>
        <origin xyz="0 0 0.63" rpy="0.0 -1.047 0"/>
        <axis xyz="0 -1 0"/>
        <limit lower="-0.349" upper="0.349"/>
        <dynamics damping="0.003" friction="0.0"/>
    </joint>
    <link name="link-branch-B15L3P12">
        <visual>
            <geometry>
                <cylinder length="0.026" radius="0.028"/>
            </geometry>
            <origin xyz="0 0 0.013" rpy="0 0 0"/>
            <material name="green">
                <color rgba="0.1 1 0.2 1"/>
            </material>
        </visual>
        <collision>
            <geometry>
                <cylinder length="0.026" radius="0.028"/>
            </geometry>
            <origin xyz="0 0 0.013" rpy="0 0 0"/>
        </collision>
        <inertial>
            <mass value="0.003"/>
            <inertia ixx="0.0" ixy="0" ixz="0" iyy="0.0" iyz="0" izz="0.0"/>
            <origin xyz="0 0 0.013" rpy="0 0 0"/>
        </inertial>
    </link>
<!-- Joint & Link: branch-B16L3P12 Branch Id:16 Level: 3, Child idx:3 )-->
<joint name="joint-branch-B12L2P1-to-branch-B16L3P12" type="revolute">
        <parent link="link-branch-B12L2P1"/>
        <child link="link-branch-B16L3P12"/>
        <origin xyz="0 0 0.63" rpy="0.0 1.047 0"/>
        <axis xyz="0 1 0"/>
        <limit lower="-0.349" upper="0.349"/>
        <dynamics damping="0.003" friction="0.0"/>
    </joint>
    <link name="link-branch-B16L3P12">
        <visual>
            <geometry>
                <cylinder length="0.026" radius="0.028"/>
            </geometry>
            <origin xyz="0 0 0.013" rpy="0 0 0"/>
            <material name="green">
                <color rgba="0.1 1 0.2 1"/>
            </material>
        </visual>
        <collision>
            <geometry>
                <cylinder length="0.026" radius="0.028"/>
            </geometry>
            <origin xyz="0 0 0.013" rpy="0 0 0"/>
        </collision>
        <inertial>
            <mass value="0.003"/>
            <inertia ixx="0.0" ixy="0" ixz="0" iyy="0.0" iyz="0" izz="0.0"/>
            <origin xyz="0 0 0.013" rpy="0 0 0"/>
        </inertial>
    </link>
<!-- Joint & Link: branch-B18L3P17 Branch Id:18 Level: 3, Child idx:0 )-->
<joint name="joint-branch-B17L2P1-to-branch-B18L3P17" type="revolute">
        <parent link="link-branch-B17L2P1"/>
        <child link="link-branch-B18L3P17"/>
        <origin xyz="0 0 0.63" rpy="-1.047 0.0 0"/>
        <axis xyz="-1 0 0"/>
        <limit lower="-0.349" upper="0.349"/>
        <dynamics damping="0.003" friction="0.0"/>
    </joint>
    <link name="link-branch-B18L3P17">
        <visual>
            <geometry>
                <cylinder length="0.026" radius="0.028"/>
            </geometry>
            <origin xyz="0 0 0.013" rpy="0 0 0"/>
            <material name="green">
                <color rgba="0.1 1 0.2 1"/>
            </material>
        </visual>
        <collision>
            <geometry>
                <cylinder length="0.026" radius="0.028"/>
            </geometry>
            <origin xyz="0 0 0.013" rpy="0 0 0"/>
        </collision>
        <inertial>
            <mass value="0.003"/>
            <inertia ixx="0.0" ixy="0" ixz="0" iyy="0.0" iyz="0" izz="0.0"/>
            <origin xyz="0 0 0.013" rpy="0 0 0"/>
        </inertial>
    </link>
<!-- Joint & Link: branch-B19L3P17 Branch Id:19 Level: 3, Child idx:1 )-->
<joint name="joint-branch-B17L2P1-to-branch-B19L3P17" type="revolute">
        <parent link="link-branch-B17L2P1"/>
        <child link="link-branch-B19L3P17"/>
        <origin xyz="0 0 0.63" rpy="1.047 0.0 0"/>
        <axis xyz="1 0 0"/>
        <limit lower="-0.349" upper="0.349"/>
        <dynamics damping="0.003" friction="0.0"/>
    </joint>
    <link name="link-branch-B19L3P17">
        <visual>
            <geometry>
                <cylinder length="0.026" radius="0.028"/>
            </geometry>
            <origin xyz="0 0 0.013" rpy="0 0 0"/>
            <material name="green">
                <color rgba="0.1 1 0.2 1"/>
            </material>
        </visual>
        <collision>
            <geometry>
                <cylinder length="0.026" radius="0.028"/>
            </geometry>
            <origin xyz="0 0 0.013" rpy="0 0 0"/>
        </collision>
        <inertial>
            <mass value="0.003"/>
            <inertia ixx="0.0" ixy="0" ixz="0" iyy="0.0" iyz="0" izz="0.0"/>
            <origin xyz="0 0 0.013" rpy="0 0 0"/>
        </inertial>
    </link>
<!-- Joint & Link: branch-B20L3P17 Branch Id:20 Level: 3, Child idx:2 )-->
<joint name="joint-branch-B17L2P1-to-branch-B20L3P17" type="revolute">
        <parent link="link-branch-B17L2P1"/>
        <child link="link-branch-B20L3P17"/>
        <origin xyz="0 0 0.63" rpy="0.0 -1.047 0"/>
        <axis xyz="0 -1 0"/>
        <limit lower="-0.349" upper="0.349"/>
        <dynamics damping="0.003" friction="0.0"/>
    </joint>
    <link name="link-branch-B20L3P17">
        <visual>
            <geometry>
                <cylinder length="0.026" radius="0.028"/>
            </geometry>
            <origin xyz="0 0 0.013" rpy="0 0 0"/>
            <material name="green">
                <color rgba="0.1 1 0.2 1"/>
            </material>
        </visual>
        <collision>
            <geometry>
                <cylinder length="0.026" radius="0.028"/>
            </geometry>
            <origin xyz="0 0 0.013" rpy="0 0 0"/>
        </collision>
        <inertial>
            <mass value="0.003"/>
            <inertia ixx="0.0" ixy="0" ixz="0" iyy="0.0" iyz="0" izz="0.0"/>
            <origin xyz="0 0 0.013" rpy="0 0 0"/>
        </inertial>
    </link>
<!-- Joint & Link: branch-B21L3P17 Branch Id:21 Level: 3, Child idx:3 )-->
<joint name="joint-branch-B17L2P1-to-branch-B21L3P17" type="revolute">
        <parent link="link-branch-B17L2P1"/>
        <child link="link-branch-B21L3P17"/>
        <origin xyz="0 0 0.63" rpy="0.0 1.047 0"/>
        <axis xyz="0 1 0"/>
        <limit lower="-0.349" upper="0.349"/>
        <dynamics damping="0.003" friction="0.0"/>
    </joint>
    <link name="link-branch-B21L3P17">
        <visual>
            <geometry>
                <cylinder length="0.026" radius="0.028"/>
            </geometry>
            <origin xyz="0 0 0.013" rpy="0 0 0"/>
            <material name="green">
                <color rgba="0.1 1 0.2 1"/>
            </material>
        </visual>
        <collision>
            <geometry>
                <cylinder length="0.026" radius="0.028"/>
            </geometry>
            <origin xyz="0 0 0.013" rpy="0 0 0"/>
        </collision>
        <inertial>
            <mass value="0.003"/>
            <inertia ixx="0.0" ixy="0" ixz="0" iyy="0.0" iyz="0" izz="0.0"/>
            <origin xyz="0 0 0.013" rpy="0 0 0"/>
        </inertial>
    </link>
<!-- Joint & Link: branch-B24L3P23 Branch Id:24 Level: 3, Child idx:0 )-->
<joint name="joint-branch-B23L2P22-to-branch-B24L3P23" type="revolute">
        <parent link="link-branch-B23L2P22"/>
        <child link="link-branch-B24L3P23"/>
        <origin xyz="0 0 0.63" rpy="-1.047 0.0 0"/>
        <axis xyz="-1 0 0"/>
        <limit lower="-0.349" upper="0.349"/>
        <dynamics damping="0.003" friction="0.0"/>
    </joint>
    <link name="link-branch-B24L3P23">
        <visual>
            <geometry>
                <cylinder length="0.026" radius="0.028"/>
            </geometry>
            <origin xyz="0 0 0.013" rpy="0 0 0"/>
            <material name="green">
                <color rgba="0.1 1 0.2 1"/>
            </material>
        </visual>
        <collision>
            <geometry>
                <cylinder length="0.026" radius="0.028"/>
            </geometry>
            <origin xyz="0 0 0.013" rpy="0 0 0"/>
        </collision>
        <inertial>
            <mass value="0.003"/>
            <inertia ixx="0.0" ixy="0" ixz="0" iyy="0.0" iyz="0" izz="0.0"/>
            <origin xyz="0 0 0.013" rpy="0 0 0"/>
        </inertial>
    </link>
<!-- Joint & Link: branch-B25L3P23 Branch Id:25 Level: 3, Child idx:1 )-->
<joint name="joint-branch-B23L2P22-to-branch-B25L3P23" type="revolute">
        <parent link="link-branch-B23L2P22"/>
        <child link="link-branch-B25L3P23"/>
        <origin xyz="0 0 0.63" rpy="1.047 0.0 0"/>
        <axis xyz="1 0 0"/>
        <limit lower="-0.349" upper="0.349"/>
        <dynamics damping="0.003" friction="0.0"/>
    </joint>
    <link name="link-branch-B25L3P23">
        <visual>
            <geometry>
                <cylinder length="0.026" radius="0.028"/>
            </geometry>
            <origin xyz="0 0 0.013" rpy="0 0 0"/>
            <material name="green">
                <color rgba="0.1 1 0.2 1"/>
            </material>
        </visual>
        <collision>
            <geometry>
                <cylinder length="0.026" radius="0.028"/>
            </geometry>
            <origin xyz="0 0 0.013" rpy="0 0 0"/>
        </collision>
        <inertial>
            <mass value="0.003"/>
            <inertia ixx="0.0" ixy="0" ixz="0" iyy="0.0" iyz="0" izz="0.0"/>
            <origin xyz="0 0 0.013" rpy="0 0 0"/>
        </inertial>
    </link>
<!-- Joint & Link: branch-B26L3P23 Branch Id:26 Level: 3, Child idx:2 )-->
<joint name="joint-branch-B23L2P22-to-branch-B26L3P23" type="revolute">
        <parent link="link-branch-B23L2P22"/>
        <child link="link-branch-B26L3P23"/>
        <origin xyz="0 0 0.63" rpy="0.0 -1.047 0"/>
        <axis xyz="0 -1 0"/>
        <limit lower="-0.349" upper="0.349"/>
        <dynamics damping="0.003" friction="0.0"/>
    </joint>
    <link name="link-branch-B26L3P23">
        <visual>
            <geometry>
                <cylinder length="0.026" radius="0.028"/>
            </geometry>
            <origin xyz="0 0 0.013" rpy="0 0 0"/>
            <material name="green">
                <color rgba="0.1 1 0.2 1"/>
            </material>
        </visual>
        <collision>
            <geometry>
                <cylinder length="0.026" radius="0.028"/>
            </geometry>
            <origin xyz="0 0 0.013" rpy="0 0 0"/>
        </collision>
        <inertial>
            <mass value="0.003"/>
            <inertia ixx="0.0" ixy="0" ixz="0" iyy="0.0" iyz="0" izz="0.0"/>
            <origin xyz="0 0 0.013" rpy="0 0 0"/>
        </inertial>
    </link>
<!-- Joint & Link: branch-B27L3P23 Branch Id:27 Level: 3, Child idx:3 )-->
<joint name="joint-branch-B23L2P22-to-branch-B27L3P23" type="revolute">
        <parent link="link-branch-B23L2P22"/>
        <child link="link-branch-B27L3P23"/>
        <origin xyz="0 0 0.63" rpy="0.0 1.047 0"/>
        <axis xyz="0 1 0"/>
        <limit lower="-0.349" upper="0.349"/>
        <dynamics damping="0.003" friction="0.0"/>
    </joint>
    <link name="link-branch-B27L3P23">
        <visual>
            <geometry>
                <cylinder length="0.026" radius="0.028"/>
            </geometry>
            <origin xyz="0 0 0.013" rpy="0 0 0"/>
            <material name="green">
                <color rgba="0.1 1 0.2 1"/>
            </material>
        </visual>
        <collision>
            <geometry>
                <cylinder length="0.026" radius="0.028"/>
            </geometry>
            <origin xyz="0 0 0.013" rpy="0 0 0"/>
        </collision>
        <inertial>
            <mass value="0.003"/>
            <inertia ixx="0.0" ixy="0" ixz="0" iyy="0.0" iyz="0" izz="0.0"/>
            <origin xyz="0 0 0.013" rpy="0 0 0"/>
        </inertial>
    </link>
<!-- Joint & Link: branch-B29L3P28 Branch Id:29 Level: 3, Child idx:0 )-->
<joint name="joint-branch-B28L2P22-to-branch-B29L3P28" type="revolute">
        <parent link="link-branch-B28L2P22"/>
        <child link="link-branch-B29L3P28"/>
        <origin xyz="0 0 0.63" rpy="-1.047 0.0 0"/>
        <axis xyz="-1 0 0"/>
        <limit lower="-0.349" upper="0.349"/>
        <dynamics damping="0.003" friction="0.0"/>
    </joint>
    <link name="link-branch-B29L3P28">
        <visual>
            <geometry>
                <cylinder length="0.026" radius="0.028"/>
            </geometry>
            <origin xyz="0 0 0.013" rpy="0 0 0"/>
            <material name="green">
                <color rgba="0.1 1 0.2 1"/>
            </material>
        </visual>
        <collision>
            <geometry>
                <cylinder length="0.026" radius="0.028"/>
            </geometry>
            <origin xyz="0 0 0.013" rpy="0 0 0"/>
        </collision>
        <inertial>
            <mass value="0.003"/>
            <inertia ixx="0.0" ixy="0" ixz="0" iyy="0.0" iyz="0" izz="0.0"/>
            <origin xyz="0 0 0.013" rpy="0 0 0"/>
        </inertial>
    </link>
<!-- Joint & Link: branch-B30L3P28 Branch Id:30 Level: 3, Child idx:1 )-->
<joint name="joint-branch-B28L2P22-to-branch-B30L3P28" type="revolute">
        <parent link="link-branch-B28L2P22"/>
        <child link="link-branch-B30L3P28"/>
        <origin xyz="0 0 0.63" rpy="1.047 0.0 0"/>
        <axis xyz="1 0 0"/>
        <limit lower="-0.349" upper="0.349"/>
        <dynamics damping="0.003" friction="0.0"/>
    </joint>
    <link name="link-branch-B30L3P28">
        <visual>
            <geometry>
                <cylinder length="0.026" radius="0.028"/>
            </geometry>
            <origin xyz="0 0 0.013" rpy="0 0 0"/>
            <material name="green">
                <color rgba="0.1 1 0.2 1"/>
            </material>
        </visual>
        <collision>
            <geometry>
                <cylinder length="0.026" radius="0.028"/>
            </geometry>
            <origin xyz="0 0 0.013" rpy="0 0 0"/>
        </collision>
        <inertial>
            <mass value="0.003"/>
            <inertia ixx="0.0" ixy="0" ixz="0" iyy="0.0" iyz="0" izz="0.0"/>
            <origin xyz="0 0 0.013" rpy="0 0 0"/>
        </inertial>
    </link>
<!-- Joint & Link: branch-B31L3P28 Branch Id:31 Level: 3, Child idx:2 )-->
<joint name="joint-branch-B28L2P22-to-branch-B31L3P28" type="revolute">
        <parent link="link-branch-B28L2P22"/>
        <child link="link-branch-B31L3P28"/>
        <origin xyz="0 0 0.63" rpy="0.0 -1.047 0"/>
        <axis xyz="0 -1 0"/>
        <limit lower="-0.349" upper="0.349"/>
        <dynamics damping="0.003" friction="0.0"/>
    </joint>
    <link name="link-branch-B31L3P28">
        <visual>
            <geometry>
                <cylinder length="0.026" radius="0.028"/>
            </geometry>
            <origin xyz="0 0 0.013" rpy="0 0 0"/>
            <material name="green">
                <color rgba="0.1 1 0.2 1"/>
            </material>
        </visual>
        <collision>
            <geometry>
                <cylinder length="0.026" radius="0.028"/>
            </geometry>
            <origin xyz="0 0 0.013" rpy="0 0 0"/>
        </collision>
        <inertial>
            <mass value="0.003"/>
            <inertia ixx="0.0" ixy="0" ixz="0" iyy="0.0" iyz="0" izz="0.0"/>
            <origin xyz="0 0 0.013" rpy="0 0 0"/>
        </inertial>
    </link>
<!-- Joint & Link: branch-B32L3P28 Branch Id:32 Level: 3, Child idx:3 )-->
<joint name="joint-branch-B28L2P22-to-branch-B32L3P28" type="revolute">
        <parent link="link-branch-B28L2P22"/>
        <child link="link-branch-B32L3P28"/>
        <origin xyz="0 0 0.63" rpy="0.0 1.047 0"/>
        <axis xyz="0 1 0"/>
        <limit lower="-0.349" upper="0.349"/>
        <dynamics damping="0.003" friction="0.0"/>
    </joint>
    <link name="link-branch-B32L3P28">
        <visual>
            <geometry>
                <cylinder length="0.026" radius="0.028"/>
            </geometry>
            <origin xyz="0 0 0.013" rpy="0 0 0"/>
            <material name="green">
                <color rgba="0.1 1 0.2 1"/>
            </material>
        </visual>
        <collision>
            <geometry>
                <cylinder length="0.026" radius="0.028"/>
            </geometry>
            <origin xyz="0 0 0.013" rpy="0 0 0"/>
        </collision>
        <inertial>
            <mass value="0.003"/>
            <inertia ixx="0.0" ixy="0" ixz="0" iyy="0.0" iyz="0" izz="0.0"/>
            <origin xyz="0 0 0.013" rpy="0 0 0"/>
        </inertial>
    </link>
<!-- Joint & Link: branch-B34L3P33 Branch Id:34 Level: 3, Child idx:0 )-->
<joint name="joint-branch-B33L2P22-to-branch-B34L3P33" type="revolute">
        <parent link="link-branch-B33L2P22"/>
        <child link="link-branch-B34L3P33"/>
        <origin xyz="0 0 0.63" rpy="-1.047 0.0 0"/>
        <axis xyz="-1 0 0"/>
        <limit lower="-0.349" upper="0.349"/>
        <dynamics damping="0.003" friction="0.0"/>
    </joint>
    <link name="link-branch-B34L3P33">
        <visual>
            <geometry>
                <cylinder length="0.026" radius="0.028"/>
            </geometry>
            <origin xyz="0 0 0.013" rpy="0 0 0"/>
            <material name="green">
                <color rgba="0.1 1 0.2 1"/>
            </material>
        </visual>
        <collision>
            <geometry>
                <cylinder length="0.026" radius="0.028"/>
            </geometry>
            <origin xyz="0 0 0.013" rpy="0 0 0"/>
        </collision>
        <inertial>
            <mass value="0.003"/>
            <inertia ixx="0.0" ixy="0" ixz="0" iyy="0.0" iyz="0" izz="0.0"/>
            <origin xyz="0 0 0.013" rpy="0 0 0"/>
        </inertial>
    </link>
<!-- Joint & Link: branch-B35L3P33 Branch Id:35 Level: 3, Child idx:1 )-->
<joint name="joint-branch-B33L2P22-to-branch-B35L3P33" type="revolute">
        <parent link="link-branch-B33L2P22"/>
        <child link="link-branch-B35L3P33"/>
        <origin xyz="0 0 0.63" rpy="1.047 0.0 0"/>
        <axis xyz="1 0 0"/>
        <limit lower="-0.349" upper="0.349"/>
        <dynamics damping="0.003" friction="0.0"/>
    </joint>
    <link name="link-branch-B35L3P33">
        <visual>
            <geometry>
                <cylinder length="0.026" radius="0.028"/>
            </geometry>
            <origin xyz="0 0 0.013" rpy="0 0 0"/>
            <material name="green">
                <color rgba="0.1 1 0.2 1"/>
            </material>
        </visual>
        <collision>
            <geometry>
                <cylinder length="0.026" radius="0.028"/>
            </geometry>
            <origin xyz="0 0 0.013" rpy="0 0 0"/>
        </collision>
        <inertial>
            <mass value="0.003"/>
            <inertia ixx="0.0" ixy="0" ixz="0" iyy="0.0" iyz="0" izz="0.0"/>
            <origin xyz="0 0 0.013" rpy="0 0 0"/>
        </inertial>
    </link>
<!-- Joint & Link: branch-B36L3P33 Branch Id:36 Level: 3, Child idx:2 )-->
<joint name="joint-branch-B33L2P22-to-branch-B36L3P33" type="revolute">
        <parent link="link-branch-B33L2P22"/>
        <child link="link-branch-B36L3P33"/>
        <origin xyz="0 0 0.63" rpy="0.0 -1.047 0"/>
        <axis xyz="0 -1 0"/>
        <limit lower="-0.349" upper="0.349"/>
        <dynamics damping="0.003" friction="0.0"/>
    </joint>
    <link name="link-branch-B36L3P33">
        <visual>
            <geometry>
                <cylinder length="0.026" radius="0.028"/>
            </geometry>
            <origin xyz="0 0 0.013" rpy="0 0 0"/>
            <material name="green">
                <color rgba="0.1 1 0.2 1"/>
            </material>
        </visual>
        <collision>
            <geometry>
                <cylinder length="0.026" radius="0.028"/>
            </geometry>
            <origin xyz="0 0 0.013" rpy="0 0 0"/>
        </collision>
        <inertial>
            <mass value="0.003"/>
            <inertia ixx="0.0" ixy="0" ixz="0" iyy="0.0" iyz="0" izz="0.0"/>
            <origin xyz="0 0 0.013" rpy="0 0 0"/>
        </inertial>
    </link>
<!-- Joint & Link: branch-B37L3P33 Branch Id:37 Level: 3, Child idx:3 )-->
<joint name="joint-branch-B33L2P22-to-branch-B37L3P33" type="revolute">
        <parent link="link-branch-B33L2P22"/>
        <child link="link-branch-B37L3P33"/>
        <origin xyz="0 0 0.63" rpy="0.0 1.047 0"/>
        <axis xyz="0 1 0"/>
        <limit lower="-0.349" upper="0.349"/>
        <dynamics damping="0.003" friction="0.0"/>
    </joint>
    <link name="link-branch-B37L3P33">
        <visual>
            <geometry>
                <cylinder length="0.026" radius="0.028"/>
            </geometry>
            <origin xyz="0 0 0.013" rpy="0 0 0"/>
            <material name="green">
                <color rgba="0.1 1 0.2 1"/>
            </material>
        </visual>
        <collision>
            <geometry>
                <cylinder length="0.026" radius="0.028"/>
            </geometry>
            <origin xyz="0 0 0.013" rpy="0 0 0"/>
        </collision>
        <inertial>
            <mass value="0.003"/>
            <inertia ixx="0.0" ixy="0" ixz="0" iyy="0.0" iyz="0" izz="0.0"/>
            <origin xyz="0 0 0.013" rpy="0 0 0"/>
        </inertial>
    </link>
<!-- Joint & Link: branch-B39L3P38 Branch Id:39 Level: 3, Child idx:0 )-->
<joint name="joint-branch-B38L2P22-to-branch-B39L3P38" type="revolute">
        <parent link="link-branch-B38L2P22"/>
        <child link="link-branch-B39L3P38"/>
        <origin xyz="0 0 0.63" rpy="-1.047 0.0 0"/>
        <axis xyz="-1 0 0"/>
        <limit lower="-0.349" upper="0.349"/>
        <dynamics damping="0.003" friction="0.0"/>
    </joint>
    <link name="link-branch-B39L3P38">
        <visual>
            <geometry>
                <cylinder length="0.026" radius="0.028"/>
            </geometry>
            <origin xyz="0 0 0.013" rpy="0 0 0"/>
            <material name="green">
                <color rgba="0.1 1 0.2 1"/>
            </material>
        </visual>
        <collision>
            <geometry>
                <cylinder length="0.026" radius="0.028"/>
            </geometry>
            <origin xyz="0 0 0.013" rpy="0 0 0"/>
        </collision>
        <inertial>
            <mass value="0.003"/>
            <inertia ixx="0.0" ixy="0" ixz="0" iyy="0.0" iyz="0" izz="0.0"/>
            <origin xyz="0 0 0.013" rpy="0 0 0"/>
        </inertial>
    </link>
<!-- Joint & Link: branch-B40L3P38 Branch Id:40 Level: 3, Child idx:1 )-->
<joint name="joint-branch-B38L2P22-to-branch-B40L3P38" type="revolute">
        <parent link="link-branch-B38L2P22"/>
        <child link="link-branch-B40L3P38"/>
        <origin xyz="0 0 0.63" rpy="1.047 0.0 0"/>
        <axis xyz="1 0 0"/>
        <limit lower="-0.349" upper="0.349"/>
        <dynamics damping="0.003" friction="0.0"/>
    </joint>
    <link name="link-branch-B40L3P38">
        <visual>
            <geometry>
                <cylinder length="0.026" radius="0.028"/>
            </geometry>
            <origin xyz="0 0 0.013" rpy="0 0 0"/>
            <material name="green">
                <color rgba="0.1 1 0.2 1"/>
            </material>
        </visual>
        <collision>
            <geometry>
                <cylinder length="0.026" radius="0.028"/>
            </geometry>
            <origin xyz="0 0 0.013" rpy="0 0 0"/>
        </collision>
        <inertial>
            <mass value="0.003"/>
            <inertia ixx="0.0" ixy="0" ixz="0" iyy="0.0" iyz="0" izz="0.0"/>
            <origin xyz="0 0 0.013" rpy="0 0 0"/>
        </inertial>
    </link>
<!-- Joint & Link: branch-B41L3P38 Branch Id:41 Level: 3, Child idx:2 )-->
<joint name="joint-branch-B38L2P22-to-branch-B41L3P38" type="revolute">
        <parent link="link-branch-B38L2P22"/>
        <child link="link-branch-B41L3P38"/>
        <origin xyz="0 0 0.63" rpy="0.0 -1.047 0"/>
        <axis xyz="0 -1 0"/>
        <limit lower="-0.349" upper="0.349"/>
        <dynamics damping="0.003" friction="0.0"/>
    </joint>
    <link name="link-branch-B41L3P38">
        <visual>
            <geometry>
                <cylinder length="0.026" radius="0.028"/>
            </geometry>
            <origin xyz="0 0 0.013" rpy="0 0 0"/>
            <material name="green">
                <color rgba="0.1 1 0.2 1"/>
            </material>
        </visual>
        <collision>
            <geometry>
                <cylinder length="0.026" radius="0.028"/>
            </geometry>
            <origin xyz="0 0 0.013" rpy="0 0 0"/>
        </collision>
        <inertial>
            <mass value="0.003"/>
            <inertia ixx="0.0" ixy="0" ixz="0" iyy="0.0" iyz="0" izz="0.0"/>
            <origin xyz="0 0 0.013" rpy="0 0 0"/>
        </inertial>
    </link>
<!-- Joint & Link: branch-B42L3P38 Branch Id:42 Level: 3, Child idx:3 )-->
<joint name="joint-branch-B38L2P22-to-branch-B42L3P38" type="revolute">
        <parent link="link-branch-B38L2P22"/>
        <child link="link-branch-B42L3P38"/>
        <origin xyz="0 0 0.63" rpy="0.0 1.047 0"/>
        <axis xyz="0 1 0"/>
        <limit lower="-0.349" upper="0.349"/>
        <dynamics damping="0.003" friction="0.0"/>
    </joint>
    <link name="link-branch-B42L3P38">
        <visual>
            <geometry>
                <cylinder length="0.026" radius="0.028"/>
            </geometry>
            <origin xyz="0 0 0.013" rpy="0 0 0"/>
            <material name="green">
                <color rgba="0.1 1 0.2 1"/>
            </material>
        </visual>
        <collision>
            <geometry>
                <cylinder length="0.026" radius="0.028"/>
            </geometry>
            <origin xyz="0 0 0.013" rpy="0 0 0"/>
        </collision>
        <inertial>
            <mass value="0.003"/>
            <inertia ixx="0.0" ixy="0" ixz="0" iyy="0.0" iyz="0" izz="0.0"/>
            <origin xyz="0 0 0.013" rpy="0 0 0"/>
        </inertial>
    </link>
<!-- Joint & Link: branch-B45L3P44 Branch Id:45 Level: 3, Child idx:0 )-->
<joint name="joint-branch-B44L2P43-to-branch-B45L3P44" type="revolute">
        <parent link="link-branch-B44L2P43"/>
        <child link="link-branch-B45L3P44"/>
        <origin xyz="0 0 0.63" rpy="-1.047 0.0 0"/>
        <axis xyz="-1 0 0"/>
        <limit lower="-0.349" upper="0.349"/>
        <dynamics damping="0.003" friction="0.0"/>
    </joint>
    <link name="link-branch-B45L3P44">
        <visual>
            <geometry>
                <cylinder length="0.026" radius="0.028"/>
            </geometry>
            <origin xyz="0 0 0.013" rpy="0 0 0"/>
            <material name="green">
                <color rgba="0.1 1 0.2 1"/>
            </material>
        </visual>
        <collision>
            <geometry>
                <cylinder length="0.026" radius="0.028"/>
            </geometry>
            <origin xyz="0 0 0.013" rpy="0 0 0"/>
        </collision>
        <inertial>
            <mass value="0.003"/>
            <inertia ixx="0.0" ixy="0" ixz="0" iyy="0.0" iyz="0" izz="0.0"/>
            <origin xyz="0 0 0.013" rpy="0 0 0"/>
        </inertial>
    </link>
<!-- Joint & Link: branch-B46L3P44 Branch Id:46 Level: 3, Child idx:1 )-->
<joint name="joint-branch-B44L2P43-to-branch-B46L3P44" type="revolute">
        <parent link="link-branch-B44L2P43"/>
        <child link="link-branch-B46L3P44"/>
        <origin xyz="0 0 0.63" rpy="1.047 0.0 0"/>
        <axis xyz="1 0 0"/>
        <limit lower="-0.349" upper="0.349"/>
        <dynamics damping="0.003" friction="0.0"/>
    </joint>
    <link name="link-branch-B46L3P44">
        <visual>
            <geometry>
                <cylinder length="0.026" radius="0.028"/>
            </geometry>
            <origin xyz="0 0 0.013" rpy="0 0 0"/>
            <material name="green">
                <color rgba="0.1 1 0.2 1"/>
            </material>
        </visual>
        <collision>
            <geometry>
                <cylinder length="0.026" radius="0.028"/>
            </geometry>
            <origin xyz="0 0 0.013" rpy="0 0 0"/>
        </collision>
        <inertial>
            <mass value="0.003"/>
            <inertia ixx="0.0" ixy="0" ixz="0" iyy="0.0" iyz="0" izz="0.0"/>
            <origin xyz="0 0 0.013" rpy="0 0 0"/>
        </inertial>
    </link>
<!-- Joint & Link: branch-B47L3P44 Branch Id:47 Level: 3, Child idx:2 )-->
<joint name="joint-branch-B44L2P43-to-branch-B47L3P44" type="revolute">
        <parent link="link-branch-B44L2P43"/>
        <child link="link-branch-B47L3P44"/>
        <origin xyz="0 0 0.63" rpy="0.0 -1.047 0"/>
        <axis xyz="0 -1 0"/>
        <limit lower="-0.349" upper="0.349"/>
        <dynamics damping="0.003" friction="0.0"/>
    </joint>
    <link name="link-branch-B47L3P44">
        <visual>
            <geometry>
                <cylinder length="0.026" radius="0.028"/>
            </geometry>
            <origin xyz="0 0 0.013" rpy="0 0 0"/>
            <material name="green">
                <color rgba="0.1 1 0.2 1"/>
            </material>
        </visual>
        <collision>
            <geometry>
                <cylinder length="0.026" radius="0.028"/>
            </geometry>
            <origin xyz="0 0 0.013" rpy="0 0 0"/>
        </collision>
        <inertial>
            <mass value="0.003"/>
            <inertia ixx="0.0" ixy="0" ixz="0" iyy="0.0" iyz="0" izz="0.0"/>
            <origin xyz="0 0 0.013" rpy="0 0 0"/>
        </inertial>
    </link>
<!-- Joint & Link: branch-B48L3P44 Branch Id:48 Level: 3, Child idx:3 )-->
<joint name="joint-branch-B44L2P43-to-branch-B48L3P44" type="revolute">
        <parent link="link-branch-B44L2P43"/>
        <child link="link-branch-B48L3P44"/>
        <origin xyz="0 0 0.63" rpy="0.0 1.047 0"/>
        <axis xyz="0 1 0"/>
        <limit lower="-0.349" upper="0.349"/>
        <dynamics damping="0.003" friction="0.0"/>
    </joint>
    <link name="link-branch-B48L3P44">
        <visual>
            <geometry>
                <cylinder length="0.026" radius="0.028"/>
            </geometry>
            <origin xyz="0 0 0.013" rpy="0 0 0"/>
            <material name="green">
                <color rgba="0.1 1 0.2 1"/>
            </material>
        </visual>
        <collision>
            <geometry>
                <cylinder length="0.026" radius="0.028"/>
            </geometry>
            <origin xyz="0 0 0.013" rpy="0 0 0"/>
        </collision>
        <inertial>
            <mass value="0.003"/>
            <inertia ixx="0.0" ixy="0" ixz="0" iyy="0.0" iyz="0" izz="0.0"/>
            <origin xyz="0 0 0.013" rpy="0 0 0"/>
        </inertial>
    </link>
<!-- Joint & Link: branch-B50L3P49 Branch Id:50 Level: 3, Child idx:0 )-->
<joint name="joint-branch-B49L2P43-to-branch-B50L3P49" type="revolute">
        <parent link="link-branch-B49L2P43"/>
        <child link="link-branch-B50L3P49"/>
        <origin xyz="0 0 0.63" rpy="-1.047 0.0 0"/>
        <axis xyz="-1 0 0"/>
        <limit lower="-0.349" upper="0.349"/>
        <dynamics damping="0.003" friction="0.0"/>
    </joint>
    <link name="link-branch-B50L3P49">
        <visual>
            <geometry>
                <cylinder length="0.026" radius="0.028"/>
            </geometry>
            <origin xyz="0 0 0.013" rpy="0 0 0"/>
            <material name="green">
                <color rgba="0.1 1 0.2 1"/>
            </material>
        </visual>
        <collision>
            <geometry>
                <cylinder length="0.026" radius="0.028"/>
            </geometry>
            <origin xyz="0 0 0.013" rpy="0 0 0"/>
        </collision>
        <inertial>
            <mass value="0.003"/>
            <inertia ixx="0.0" ixy="0" ixz="0" iyy="0.0" iyz="0" izz="0.0"/>
            <origin xyz="0 0 0.013" rpy="0 0 0"/>
        </inertial>
    </link>
<!-- Joint & Link: branch-B51L3P49 Branch Id:51 Level: 3, Child idx:1 )-->
<joint name="joint-branch-B49L2P43-to-branch-B51L3P49" type="revolute">
        <parent link="link-branch-B49L2P43"/>
        <child link="link-branch-B51L3P49"/>
        <origin xyz="0 0 0.63" rpy="1.047 0.0 0"/>
        <axis xyz="1 0 0"/>
        <limit lower="-0.349" upper="0.349"/>
        <dynamics damping="0.003" friction="0.0"/>
    </joint>
    <link name="link-branch-B51L3P49">
        <visual>
            <geometry>
                <cylinder length="0.026" radius="0.028"/>
            </geometry>
            <origin xyz="0 0 0.013" rpy="0 0 0"/>
            <material name="green">
                <color rgba="0.1 1 0.2 1"/>
            </material>
        </visual>
        <collision>
            <geometry>
                <cylinder length="0.026" radius="0.028"/>
            </geometry>
            <origin xyz="0 0 0.013" rpy="0 0 0"/>
        </collision>
        <inertial>
            <mass value="0.003"/>
            <inertia ixx="0.0" ixy="0" ixz="0" iyy="0.0" iyz="0" izz="0.0"/>
            <origin xyz="0 0 0.013" rpy="0 0 0"/>
        </inertial>
    </link>
<!-- Joint & Link: branch-B52L3P49 Branch Id:52 Level: 3, Child idx:2 )-->
<joint name="joint-branch-B49L2P43-to-branch-B52L3P49" type="revolute">
        <parent link="link-branch-B49L2P43"/>
        <child link="link-branch-B52L3P49"/>
        <origin xyz="0 0 0.63" rpy="0.0 -1.047 0"/>
        <axis xyz="0 -1 0"/>
        <limit lower="-0.349" upper="0.349"/>
        <dynamics damping="0.003" friction="0.0"/>
    </joint>
    <link name="link-branch-B52L3P49">
        <visual>
            <geometry>
                <cylinder length="0.026" radius="0.028"/>
            </geometry>
            <origin xyz="0 0 0.013" rpy="0 0 0"/>
            <material name="green">
                <color rgba="0.1 1 0.2 1"/>
            </material>
        </visual>
        <collision>
            <geometry>
                <cylinder length="0.026" radius="0.028"/>
            </geometry>
            <origin xyz="0 0 0.013" rpy="0 0 0"/>
        </collision>
        <inertial>
            <mass value="0.003"/>
            <inertia ixx="0.0" ixy="0" ixz="0" iyy="0.0" iyz="0" izz="0.0"/>
            <origin xyz="0 0 0.013" rpy="0 0 0"/>
        </inertial>
    </link>
<!-- Joint & Link: branch-B53L3P49 Branch Id:53 Level: 3, Child idx:3 )-->
<joint name="joint-branch-B49L2P43-to-branch-B53L3P49" type="revolute">
        <parent link="link-branch-B49L2P43"/>
        <child link="link-branch-B53L3P49"/>
        <origin xyz="0 0 0.63" rpy="0.0 1.047 0"/>
        <axis xyz="0 1 0"/>
        <limit lower="-0.349" upper="0.349"/>
        <dynamics damping="0.003" friction="0.0"/>
    </joint>
    <link name="link-branch-B53L3P49">
        <visual>
            <geometry>
                <cylinder length="0.026" radius="0.028"/>
            </geometry>
            <origin xyz="0 0 0.013" rpy="0 0 0"/>
            <material name="green">
                <color rgba="0.1 1 0.2 1"/>
            </material>
        </visual>
        <collision>
            <geometry>
                <cylinder length="0.026" radius="0.028"/>
            </geometry>
            <origin xyz="0 0 0.013" rpy="0 0 0"/>
        </collision>
        <inertial>
            <mass value="0.003"/>
            <inertia ixx="0.0" ixy="0" ixz="0" iyy="0.0" iyz="0" izz="0.0"/>
            <origin xyz="0 0 0.013" rpy="0 0 0"/>
        </inertial>
    </link>
<!-- Joint & Link: branch-B55L3P54 Branch Id:55 Level: 3, Child idx:0 )-->
<joint name="joint-branch-B54L2P43-to-branch-B55L3P54" type="revolute">
        <parent link="link-branch-B54L2P43"/>
        <child link="link-branch-B55L3P54"/>
        <origin xyz="0 0 0.63" rpy="-1.047 0.0 0"/>
        <axis xyz="-1 0 0"/>
        <limit lower="-0.349" upper="0.349"/>
        <dynamics damping="0.003" friction="0.0"/>
    </joint>
    <link name="link-branch-B55L3P54">
        <visual>
            <geometry>
                <cylinder length="0.026" radius="0.028"/>
            </geometry>
            <origin xyz="0 0 0.013" rpy="0 0 0"/>
            <material name="green">
                <color rgba="0.1 1 0.2 1"/>
            </material>
        </visual>
        <collision>
            <geometry>
                <cylinder length="0.026" radius="0.028"/>
            </geometry>
            <origin xyz="0 0 0.013" rpy="0 0 0"/>
        </collision>
        <inertial>
            <mass value="0.003"/>
            <inertia ixx="0.0" ixy="0" ixz="0" iyy="0.0" iyz="0" izz="0.0"/>
            <origin xyz="0 0 0.013" rpy="0 0 0"/>
        </inertial>
    </link>
<!-- Joint & Link: branch-B56L3P54 Branch Id:56 Level: 3, Child idx:1 )-->
<joint name="joint-branch-B54L2P43-to-branch-B56L3P54" type="revolute">
        <parent link="link-branch-B54L2P43"/>
        <child link="link-branch-B56L3P54"/>
        <origin xyz="0 0 0.63" rpy="1.047 0.0 0"/>
        <axis xyz="1 0 0"/>
        <limit lower="-0.349" upper="0.349"/>
        <dynamics damping="0.003" friction="0.0"/>
    </joint>
    <link name="link-branch-B56L3P54">
        <visual>
            <geometry>
                <cylinder length="0.026" radius="0.028"/>
            </geometry>
            <origin xyz="0 0 0.013" rpy="0 0 0"/>
            <material name="green">
                <color rgba="0.1 1 0.2 1"/>
            </material>
        </visual>
        <collision>
            <geometry>
                <cylinder length="0.026" radius="0.028"/>
            </geometry>
            <origin xyz="0 0 0.013" rpy="0 0 0"/>
        </collision>
        <inertial>
            <mass value="0.003"/>
            <inertia ixx="0.0" ixy="0" ixz="0" iyy="0.0" iyz="0" izz="0.0"/>
            <origin xyz="0 0 0.013" rpy="0 0 0"/>
        </inertial>
    </link>
<!-- Joint & Link: branch-B57L3P54 Branch Id:57 Level: 3, Child idx:2 )-->
<joint name="joint-branch-B54L2P43-to-branch-B57L3P54" type="revolute">
        <parent link="link-branch-B54L2P43"/>
        <child link="link-branch-B57L3P54"/>
        <origin xyz="0 0 0.63" rpy="0.0 -1.047 0"/>
        <axis xyz="0 -1 0"/>
        <limit lower="-0.349" upper="0.349"/>
        <dynamics damping="0.003" friction="0.0"/>
    </joint>
    <link name="link-branch-B57L3P54">
        <visual>
            <geometry>
                <cylinder length="0.026" radius="0.028"/>
            </geometry>
            <origin xyz="0 0 0.013" rpy="0 0 0"/>
            <material name="green">
                <color rgba="0.1 1 0.2 1"/>
            </material>
        </visual>
        <collision>
            <geometry>
                <cylinder length="0.026" radius="0.028"/>
            </geometry>
            <origin xyz="0 0 0.013" rpy="0 0 0"/>
        </collision>
        <inertial>
            <mass value="0.003"/>
            <inertia ixx="0.0" ixy="0" ixz="0" iyy="0.0" iyz="0" izz="0.0"/>
            <origin xyz="0 0 0.013" rpy="0 0 0"/>
        </inertial>
    </link>
<!-- Joint & Link: branch-B58L3P54 Branch Id:58 Level: 3, Child idx:3 )-->
<joint name="joint-branch-B54L2P43-to-branch-B58L3P54" type="revolute">
        <parent link="link-branch-B54L2P43"/>
        <child link="link-branch-B58L3P54"/>
        <origin xyz="0 0 0.63" rpy="0.0 1.047 0"/>
        <axis xyz="0 1 0"/>
        <limit lower="-0.349" upper="0.349"/>
        <dynamics damping="0.003" friction="0.0"/>
    </joint>
    <link name="link-branch-B58L3P54">
        <visual>
            <geometry>
                <cylinder length="0.026" radius="0.028"/>
            </geometry>
            <origin xyz="0 0 0.013" rpy="0 0 0"/>
            <material name="green">
                <color rgba="0.1 1 0.2 1"/>
            </material>
        </visual>
        <collision>
            <geometry>
                <cylinder length="0.026" radius="0.028"/>
            </geometry>
            <origin xyz="0 0 0.013" rpy="0 0 0"/>
        </collision>
        <inertial>
            <mass value="0.003"/>
            <inertia ixx="0.0" ixy="0" ixz="0" iyy="0.0" iyz="0" izz="0.0"/>
            <origin xyz="0 0 0.013" rpy="0 0 0"/>
        </inertial>
    </link>
<!-- Joint & Link: branch-B60L3P59 Branch Id:60 Level: 3, Child idx:0 )-->
<joint name="joint-branch-B59L2P43-to-branch-B60L3P59" type="revolute">
        <parent link="link-branch-B59L2P43"/>
        <child link="link-branch-B60L3P59"/>
        <origin xyz="0 0 0.63" rpy="-1.047 0.0 0"/>
        <axis xyz="-1 0 0"/>
        <limit lower="-0.349" upper="0.349"/>
        <dynamics damping="0.003" friction="0.0"/>
    </joint>
    <link name="link-branch-B60L3P59">
        <visual>
            <geometry>
                <cylinder length="0.026" radius="0.028"/>
            </geometry>
            <origin xyz="0 0 0.013" rpy="0 0 0"/>
            <material name="green">
                <color rgba="0.1 1 0.2 1"/>
            </material>
        </visual>
        <collision>
            <geometry>
                <cylinder length="0.026" radius="0.028"/>
            </geometry>
            <origin xyz="0 0 0.013" rpy="0 0 0"/>
        </collision>
        <inertial>
            <mass value="0.003"/>
            <inertia ixx="0.0" ixy="0" ixz="0" iyy="0.0" iyz="0" izz="0.0"/>
            <origin xyz="0 0 0.013" rpy="0 0 0"/>
        </inertial>
    </link>
<!-- Joint & Link: branch-B61L3P59 Branch Id:61 Level: 3, Child idx:1 )-->
<joint name="joint-branch-B59L2P43-to-branch-B61L3P59" type="revolute">
        <parent link="link-branch-B59L2P43"/>
        <child link="link-branch-B61L3P59"/>
        <origin xyz="0 0 0.63" rpy="1.047 0.0 0"/>
        <axis xyz="1 0 0"/>
        <limit lower="-0.349" upper="0.349"/>
        <dynamics damping="0.003" friction="0.0"/>
    </joint>
    <link name="link-branch-B61L3P59">
        <visual>
            <geometry>
                <cylinder length="0.026" radius="0.028"/>
            </geometry>
            <origin xyz="0 0 0.013" rpy="0 0 0"/>
            <material name="green">
                <color rgba="0.1 1 0.2 1"/>
            </material>
        </visual>
        <collision>
            <geometry>
                <cylinder length="0.026" radius="0.028"/>
            </geometry>
            <origin xyz="0 0 0.013" rpy="0 0 0"/>
        </collision>
        <inertial>
            <mass value="0.003"/>
            <inertia ixx="0.0" ixy="0" ixz="0" iyy="0.0" iyz="0" izz="0.0"/>
            <origin xyz="0 0 0.013" rpy="0 0 0"/>
        </inertial>
    </link>
<!-- Joint & Link: branch-B62L3P59 Branch Id:62 Level: 3, Child idx:2 )-->
<joint name="joint-branch-B59L2P43-to-branch-B62L3P59" type="revolute">
        <parent link="link-branch-B59L2P43"/>
        <child link="link-branch-B62L3P59"/>
        <origin xyz="0 0 0.63" rpy="0.0 -1.047 0"/>
        <axis xyz="0 -1 0"/>
        <limit lower="-0.349" upper="0.349"/>
        <dynamics damping="0.003" friction="0.0"/>
    </joint>
    <link name="link-branch-B62L3P59">
        <visual>
            <geometry>
                <cylinder length="0.026" radius="0.028"/>
            </geometry>
            <origin xyz="0 0 0.013" rpy="0 0 0"/>
            <material name="green">
                <color rgba="0.1 1 0.2 1"/>
            </material>
        </visual>
        <collision>
            <geometry>
                <cylinder length="0.026" radius="0.028"/>
            </geometry>
            <origin xyz="0 0 0.013" rpy="0 0 0"/>
        </collision>
        <inertial>
            <mass value="0.003"/>
            <inertia ixx="0.0" ixy="0" ixz="0" iyy="0.0" iyz="0" izz="0.0"/>
            <origin xyz="0 0 0.013" rpy="0 0 0"/>
        </inertial>
    </link>
<!-- Joint & Link: branch-B63L3P59 Branch Id:63 Level: 3, Child idx:3 )-->
<joint name="joint-branch-B59L2P43-to-branch-B63L3P59" type="revolute">
        <parent link="link-branch-B59L2P43"/>
        <child link="link-branch-B63L3P59"/>
        <origin xyz="0 0 0.63" rpy="0.0 1.047 0"/>
        <axis xyz="0 1 0"/>
        <limit lower="-0.349" upper="0.349"/>
        <dynamics damping="0.003" friction="0.0"/>
    </joint>
    <link name="link-branch-B63L3P59">
        <visual>
            <geometry>
                <cylinder length="0.026" radius="0.028"/>
            </geometry>
            <origin xyz="0 0 0.013" rpy="0 0 0"/>
            <material name="green">
                <color rgba="0.1 1 0.2 1"/>
            </material>
        </visual>
        <collision>
            <geometry>
                <cylinder length="0.026" radius="0.028"/>
            </geometry>
            <origin xyz="0 0 0.013" rpy="0 0 0"/>
        </collision>
        <inertial>
            <mass value="0.003"/>
            <inertia ixx="0.0" ixy="0" ixz="0" iyy="0.0" iyz="0" izz="0.0"/>
            <origin xyz="0 0 0.013" rpy="0 0 0"/>
        </inertial>
    </link>
<!-- Joint & Link: branch-B66L3P65 Branch Id:66 Level: 3, Child idx:0 )-->
<joint name="joint-branch-B65L2P64-to-branch-B66L3P65" type="revolute">
        <parent link="link-branch-B65L2P64"/>
        <child link="link-branch-B66L3P65"/>
        <origin xyz="0 0 0.63" rpy="-1.047 0.0 0"/>
        <axis xyz="-1 0 0"/>
        <limit lower="-0.349" upper="0.349"/>
        <dynamics damping="0.003" friction="0.0"/>
    </joint>
    <link name="link-branch-B66L3P65">
        <visual>
            <geometry>
                <cylinder length="0.026" radius="0.028"/>
            </geometry>
            <origin xyz="0 0 0.013" rpy="0 0 0"/>
            <material name="green">
                <color rgba="0.1 1 0.2 1"/>
            </material>
        </visual>
        <collision>
            <geometry>
                <cylinder length="0.026" radius="0.028"/>
            </geometry>
            <origin xyz="0 0 0.013" rpy="0 0 0"/>
        </collision>
        <inertial>
            <mass value="0.003"/>
            <inertia ixx="0.0" ixy="0" ixz="0" iyy="0.0" iyz="0" izz="0.0"/>
            <origin xyz="0 0 0.013" rpy="0 0 0"/>
        </inertial>
    </link>
<!-- Joint & Link: branch-B67L3P65 Branch Id:67 Level: 3, Child idx:1 )-->
<joint name="joint-branch-B65L2P64-to-branch-B67L3P65" type="revolute">
        <parent link="link-branch-B65L2P64"/>
        <child link="link-branch-B67L3P65"/>
        <origin xyz="0 0 0.63" rpy="1.047 0.0 0"/>
        <axis xyz="1 0 0"/>
        <limit lower="-0.349" upper="0.349"/>
        <dynamics damping="0.003" friction="0.0"/>
    </joint>
    <link name="link-branch-B67L3P65">
        <visual>
            <geometry>
                <cylinder length="0.026" radius="0.028"/>
            </geometry>
            <origin xyz="0 0 0.013" rpy="0 0 0"/>
            <material name="green">
                <color rgba="0.1 1 0.2 1"/>
            </material>
        </visual>
        <collision>
            <geometry>
                <cylinder length="0.026" radius="0.028"/>
            </geometry>
            <origin xyz="0 0 0.013" rpy="0 0 0"/>
        </collision>
        <inertial>
            <mass value="0.003"/>
            <inertia ixx="0.0" ixy="0" ixz="0" iyy="0.0" iyz="0" izz="0.0"/>
            <origin xyz="0 0 0.013" rpy="0 0 0"/>
        </inertial>
    </link>
<!-- Joint & Link: branch-B68L3P65 Branch Id:68 Level: 3, Child idx:2 )-->
<joint name="joint-branch-B65L2P64-to-branch-B68L3P65" type="revolute">
        <parent link="link-branch-B65L2P64"/>
        <child link="link-branch-B68L3P65"/>
        <origin xyz="0 0 0.63" rpy="0.0 -1.047 0"/>
        <axis xyz="0 -1 0"/>
        <limit lower="-0.349" upper="0.349"/>
        <dynamics damping="0.003" friction="0.0"/>
    </joint>
    <link name="link-branch-B68L3P65">
        <visual>
            <geometry>
                <cylinder length="0.026" radius="0.028"/>
            </geometry>
            <origin xyz="0 0 0.013" rpy="0 0 0"/>
            <material name="green">
                <color rgba="0.1 1 0.2 1"/>
            </material>
        </visual>
        <collision>
            <geometry>
                <cylinder length="0.026" radius="0.028"/>
            </geometry>
            <origin xyz="0 0 0.013" rpy="0 0 0"/>
        </collision>
        <inertial>
            <mass value="0.003"/>
            <inertia ixx="0.0" ixy="0" ixz="0" iyy="0.0" iyz="0" izz="0.0"/>
            <origin xyz="0 0 0.013" rpy="0 0 0"/>
        </inertial>
    </link>
<!-- Joint & Link: branch-B69L3P65 Branch Id:69 Level: 3, Child idx:3 )-->
<joint name="joint-branch-B65L2P64-to-branch-B69L3P65" type="revolute">
        <parent link="link-branch-B65L2P64"/>
        <child link="link-branch-B69L3P65"/>
        <origin xyz="0 0 0.63" rpy="0.0 1.047 0"/>
        <axis xyz="0 1 0"/>
        <limit lower="-0.349" upper="0.349"/>
        <dynamics damping="0.003" friction="0.0"/>
    </joint>
    <link name="link-branch-B69L3P65">
        <visual>
            <geometry>
                <cylinder length="0.026" radius="0.028"/>
            </geometry>
            <origin xyz="0 0 0.013" rpy="0 0 0"/>
            <material name="green">
                <color rgba="0.1 1 0.2 1"/>
            </material>
        </visual>
        <collision>
            <geometry>
                <cylinder length="0.026" radius="0.028"/>
            </geometry>
            <origin xyz="0 0 0.013" rpy="0 0 0"/>
        </collision>
        <inertial>
            <mass value="0.003"/>
            <inertia ixx="0.0" ixy="0" ixz="0" iyy="0.0" iyz="0" izz="0.0"/>
            <origin xyz="0 0 0.013" rpy="0 0 0"/>
        </inertial>
    </link>
<!-- Joint & Link: branch-B71L3P70 Branch Id:71 Level: 3, Child idx:0 )-->
<joint name="joint-branch-B70L2P64-to-branch-B71L3P70" type="revolute">
        <parent link="link-branch-B70L2P64"/>
        <child link="link-branch-B71L3P70"/>
        <origin xyz="0 0 0.63" rpy="-1.047 0.0 0"/>
        <axis xyz="-1 0 0"/>
        <limit lower="-0.349" upper="0.349"/>
        <dynamics damping="0.003" friction="0.0"/>
    </joint>
    <link name="link-branch-B71L3P70">
        <visual>
            <geometry>
                <cylinder length="0.026" radius="0.028"/>
            </geometry>
            <origin xyz="0 0 0.013" rpy="0 0 0"/>
            <material name="green">
                <color rgba="0.1 1 0.2 1"/>
            </material>
        </visual>
        <collision>
            <geometry>
                <cylinder length="0.026" radius="0.028"/>
            </geometry>
            <origin xyz="0 0 0.013" rpy="0 0 0"/>
        </collision>
        <inertial>
            <mass value="0.003"/>
            <inertia ixx="0.0" ixy="0" ixz="0" iyy="0.0" iyz="0" izz="0.0"/>
            <origin xyz="0 0 0.013" rpy="0 0 0"/>
        </inertial>
    </link>
<!-- Joint & Link: branch-B72L3P70 Branch Id:72 Level: 3, Child idx:1 )-->
<joint name="joint-branch-B70L2P64-to-branch-B72L3P70" type="revolute">
        <parent link="link-branch-B70L2P64"/>
        <child link="link-branch-B72L3P70"/>
        <origin xyz="0 0 0.63" rpy="1.047 0.0 0"/>
        <axis xyz="1 0 0"/>
        <limit lower="-0.349" upper="0.349"/>
        <dynamics damping="0.003" friction="0.0"/>
    </joint>
    <link name="link-branch-B72L3P70">
        <visual>
            <geometry>
                <cylinder length="0.026" radius="0.028"/>
            </geometry>
            <origin xyz="0 0 0.013" rpy="0 0 0"/>
            <material name="green">
                <color rgba="0.1 1 0.2 1"/>
            </material>
        </visual>
        <collision>
            <geometry>
                <cylinder length="0.026" radius="0.028"/>
            </geometry>
            <origin xyz="0 0 0.013" rpy="0 0 0"/>
        </collision>
        <inertial>
            <mass value="0.003"/>
            <inertia ixx="0.0" ixy="0" ixz="0" iyy="0.0" iyz="0" izz="0.0"/>
            <origin xyz="0 0 0.013" rpy="0 0 0"/>
        </inertial>
    </link>
<!-- Joint & Link: branch-B73L3P70 Branch Id:73 Level: 3, Child idx:2 )-->
<joint name="joint-branch-B70L2P64-to-branch-B73L3P70" type="revolute">
        <parent link="link-branch-B70L2P64"/>
        <child link="link-branch-B73L3P70"/>
        <origin xyz="0 0 0.63" rpy="0.0 -1.047 0"/>
        <axis xyz="0 -1 0"/>
        <limit lower="-0.349" upper="0.349"/>
        <dynamics damping="0.003" friction="0.0"/>
    </joint>
    <link name="link-branch-B73L3P70">
        <visual>
            <geometry>
                <cylinder length="0.026" radius="0.028"/>
            </geometry>
            <origin xyz="0 0 0.013" rpy="0 0 0"/>
            <material name="green">
                <color rgba="0.1 1 0.2 1"/>
            </material>
        </visual>
        <collision>
            <geometry>
                <cylinder length="0.026" radius="0.028"/>
            </geometry>
            <origin xyz="0 0 0.013" rpy="0 0 0"/>
        </collision>
        <inertial>
            <mass value="0.003"/>
            <inertia ixx="0.0" ixy="0" ixz="0" iyy="0.0" iyz="0" izz="0.0"/>
            <origin xyz="0 0 0.013" rpy="0 0 0"/>
        </inertial>
    </link>
<!-- Joint & Link: branch-B74L3P70 Branch Id:74 Level: 3, Child idx:3 )-->
<joint name="joint-branch-B70L2P64-to-branch-B74L3P70" type="revolute">
        <parent link="link-branch-B70L2P64"/>
        <child link="link-branch-B74L3P70"/>
        <origin xyz="0 0 0.63" rpy="0.0 1.047 0"/>
        <axis xyz="0 1 0"/>
        <limit lower="-0.349" upper="0.349"/>
        <dynamics damping="0.003" friction="0.0"/>
    </joint>
    <link name="link-branch-B74L3P70">
        <visual>
            <geometry>
                <cylinder length="0.026" radius="0.028"/>
            </geometry>
            <origin xyz="0 0 0.013" rpy="0 0 0"/>
            <material name="green">
                <color rgba="0.1 1 0.2 1"/>
            </material>
        </visual>
        <collision>
            <geometry>
                <cylinder length="0.026" radius="0.028"/>
            </geometry>
            <origin xyz="0 0 0.013" rpy="0 0 0"/>
        </collision>
        <inertial>
            <mass value="0.003"/>
            <inertia ixx="0.0" ixy="0" ixz="0" iyy="0.0" iyz="0" izz="0.0"/>
            <origin xyz="0 0 0.013" rpy="0 0 0"/>
        </inertial>
    </link>
<!-- Joint & Link: branch-B76L3P75 Branch Id:76 Level: 3, Child idx:0 )-->
<joint name="joint-branch-B75L2P64-to-branch-B76L3P75" type="revolute">
        <parent link="link-branch-B75L2P64"/>
        <child link="link-branch-B76L3P75"/>
        <origin xyz="0 0 0.63" rpy="-1.047 0.0 0"/>
        <axis xyz="-1 0 0"/>
        <limit lower="-0.349" upper="0.349"/>
        <dynamics damping="0.003" friction="0.0"/>
    </joint>
    <link name="link-branch-B76L3P75">
        <visual>
            <geometry>
                <cylinder length="0.026" radius="0.028"/>
            </geometry>
            <origin xyz="0 0 0.013" rpy="0 0 0"/>
            <material name="green">
                <color rgba="0.1 1 0.2 1"/>
            </material>
        </visual>
        <collision>
            <geometry>
                <cylinder length="0.026" radius="0.028"/>
            </geometry>
            <origin xyz="0 0 0.013" rpy="0 0 0"/>
        </collision>
        <inertial>
            <mass value="0.003"/>
            <inertia ixx="0.0" ixy="0" ixz="0" iyy="0.0" iyz="0" izz="0.0"/>
            <origin xyz="0 0 0.013" rpy="0 0 0"/>
        </inertial>
    </link>
<!-- Joint & Link: branch-B77L3P75 Branch Id:77 Level: 3, Child idx:1 )-->
<joint name="joint-branch-B75L2P64-to-branch-B77L3P75" type="revolute">
        <parent link="link-branch-B75L2P64"/>
        <child link="link-branch-B77L3P75"/>
        <origin xyz="0 0 0.63" rpy="1.047 0.0 0"/>
        <axis xyz="1 0 0"/>
        <limit lower="-0.349" upper="0.349"/>
        <dynamics damping="0.003" friction="0.0"/>
    </joint>
    <link name="link-branch-B77L3P75">
        <visual>
            <geometry>
                <cylinder length="0.026" radius="0.028"/>
            </geometry>
            <origin xyz="0 0 0.013" rpy="0 0 0"/>
            <material name="green">
                <color rgba="0.1 1 0.2 1"/>
            </material>
        </visual>
        <collision>
            <geometry>
                <cylinder length="0.026" radius="0.028"/>
            </geometry>
            <origin xyz="0 0 0.013" rpy="0 0 0"/>
        </collision>
        <inertial>
            <mass value="0.003"/>
            <inertia ixx="0.0" ixy="0" ixz="0" iyy="0.0" iyz="0" izz="0.0"/>
            <origin xyz="0 0 0.013" rpy="0 0 0"/>
        </inertial>
    </link>
<!-- Joint & Link: branch-B78L3P75 Branch Id:78 Level: 3, Child idx:2 )-->
<joint name="joint-branch-B75L2P64-to-branch-B78L3P75" type="revolute">
        <parent link="link-branch-B75L2P64"/>
        <child link="link-branch-B78L3P75"/>
        <origin xyz="0 0 0.63" rpy="0.0 -1.047 0"/>
        <axis xyz="0 -1 0"/>
        <limit lower="-0.349" upper="0.349"/>
        <dynamics damping="0.003" friction="0.0"/>
    </joint>
    <link name="link-branch-B78L3P75">
        <visual>
            <geometry>
                <cylinder length="0.026" radius="0.028"/>
            </geometry>
            <origin xyz="0 0 0.013" rpy="0 0 0"/>
            <material name="green">
                <color rgba="0.1 1 0.2 1"/>
            </material>
        </visual>
        <collision>
            <geometry>
                <cylinder length="0.026" radius="0.028"/>
            </geometry>
            <origin xyz="0 0 0.013" rpy="0 0 0"/>
        </collision>
        <inertial>
            <mass value="0.003"/>
            <inertia ixx="0.0" ixy="0" ixz="0" iyy="0.0" iyz="0" izz="0.0"/>
            <origin xyz="0 0 0.013" rpy="0 0 0"/>
        </inertial>
    </link>
<!-- Joint & Link: branch-B79L3P75 Branch Id:79 Level: 3, Child idx:3 )-->
<joint name="joint-branch-B75L2P64-to-branch-B79L3P75" type="revolute">
        <parent link="link-branch-B75L2P64"/>
        <child link="link-branch-B79L3P75"/>
        <origin xyz="0 0 0.63" rpy="0.0 1.047 0"/>
        <axis xyz="0 1 0"/>
        <limit lower="-0.349" upper="0.349"/>
        <dynamics damping="0.003" friction="0.0"/>
    </joint>
    <link name="link-branch-B79L3P75">
        <visual>
            <geometry>
                <cylinder length="0.026" radius="0.028"/>
            </geometry>
            <origin xyz="0 0 0.013" rpy="0 0 0"/>
            <material name="green">
                <color rgba="0.1 1 0.2 1"/>
            </material>
        </visual>
        <collision>
            <geometry>
                <cylinder length="0.026" radius="0.028"/>
            </geometry>
            <origin xyz="0 0 0.013" rpy="0 0 0"/>
        </collision>
        <inertial>
            <mass value="0.003"/>
            <inertia ixx="0.0" ixy="0" ixz="0" iyy="0.0" iyz="0" izz="0.0"/>
            <origin xyz="0 0 0.013" rpy="0 0 0"/>
        </inertial>
    </link>
<!-- Joint & Link: branch-B81L3P80 Branch Id:81 Level: 3, Child idx:0 )-->
<joint name="joint-branch-B80L2P64-to-branch-B81L3P80" type="revolute">
        <parent link="link-branch-B80L2P64"/>
        <child link="link-branch-B81L3P80"/>
        <origin xyz="0 0 0.63" rpy="-1.047 0.0 0"/>
        <axis xyz="-1 0 0"/>
        <limit lower="-0.349" upper="0.349"/>
        <dynamics damping="0.003" friction="0.0"/>
    </joint>
    <link name="link-branch-B81L3P80">
        <visual>
            <geometry>
                <cylinder length="0.026" radius="0.028"/>
            </geometry>
            <origin xyz="0 0 0.013" rpy="0 0 0"/>
            <material name="green">
                <color rgba="0.1 1 0.2 1"/>
            </material>
        </visual>
        <collision>
            <geometry>
                <cylinder length="0.026" radius="0.028"/>
            </geometry>
            <origin xyz="0 0 0.013" rpy="0 0 0"/>
        </collision>
        <inertial>
            <mass value="0.003"/>
            <inertia ixx="0.0" ixy="0" ixz="0" iyy="0.0" iyz="0" izz="0.0"/>
            <origin xyz="0 0 0.013" rpy="0 0 0"/>
        </inertial>
    </link>
<!-- Joint & Link: branch-B82L3P80 Branch Id:82 Level: 3, Child idx:1 )-->
<joint name="joint-branch-B80L2P64-to-branch-B82L3P80" type="revolute">
        <parent link="link-branch-B80L2P64"/>
        <child link="link-branch-B82L3P80"/>
        <origin xyz="0 0 0.63" rpy="1.047 0.0 0"/>
        <axis xyz="1 0 0"/>
        <limit lower="-0.349" upper="0.349"/>
        <dynamics damping="0.003" friction="0.0"/>
    </joint>
    <link name="link-branch-B82L3P80">
        <visual>
            <geometry>
                <cylinder length="0.026" radius="0.028"/>
            </geometry>
            <origin xyz="0 0 0.013" rpy="0 0 0"/>
            <material name="green">
                <color rgba="0.1 1 0.2 1"/>
            </material>
        </visual>
        <collision>
            <geometry>
                <cylinder length="0.026" radius="0.028"/>
            </geometry>
            <origin xyz="0 0 0.013" rpy="0 0 0"/>
        </collision>
        <inertial>
            <mass value="0.003"/>
            <inertia ixx="0.0" ixy="0" ixz="0" iyy="0.0" iyz="0" izz="0.0"/>
            <origin xyz="0 0 0.013" rpy="0 0 0"/>
        </inertial>
    </link>
<!-- Joint & Link: branch-B83L3P80 Branch Id:83 Level: 3, Child idx:2 )-->
<joint name="joint-branch-B80L2P64-to-branch-B83L3P80" type="revolute">
        <parent link="link-branch-B80L2P64"/>
        <child link="link-branch-B83L3P80"/>
        <origin xyz="0 0 0.63" rpy="0.0 -1.047 0"/>
        <axis xyz="0 -1 0"/>
        <limit lower="-0.349" upper="0.349"/>
        <dynamics damping="0.003" friction="0.0"/>
    </joint>
    <link name="link-branch-B83L3P80">
        <visual>
            <geometry>
                <cylinder length="0.026" radius="0.028"/>
            </geometry>
            <origin xyz="0 0 0.013" rpy="0 0 0"/>
            <material name="green">
                <color rgba="0.1 1 0.2 1"/>
            </material>
        </visual>
        <collision>
            <geometry>
                <cylinder length="0.026" radius="0.028"/>
            </geometry>
            <origin xyz="0 0 0.013" rpy="0 0 0"/>
        </collision>
        <inertial>
            <mass value="0.003"/>
            <inertia ixx="0.0" ixy="0" ixz="0" iyy="0.0" iyz="0" izz="0.0"/>
            <origin xyz="0 0 0.013" rpy="0 0 0"/>
        </inertial>
    </link>
<!-- Joint & Link: branch-B84L3P80 Branch Id:84 Level: 3, Child idx:3 )-->
<joint name="joint-branch-B80L2P64-to-branch-B84L3P80" type="revolute">
        <parent link="link-branch-B80L2P64"/>
        <child link="link-branch-B84L3P80"/>
        <origin xyz="0 0 0.63" rpy="0.0 1.047 0"/>
        <axis xyz="0 1 0"/>
        <limit lower="-0.349" upper="0.349"/>
        <dynamics damping="0.003" friction="0.0"/>
    </joint>
    <link name="link-branch-B84L3P80">
        <visual>
            <geometry>
                <cylinder length="0.026" radius="0.028"/>
            </geometry>
            <origin xyz="0 0 0.013" rpy="0 0 0"/>
            <material name="green">
                <color rgba="0.1 1 0.2 1"/>
            </material>
        </visual>
        <collision>
            <geometry>
                <cylinder length="0.026" radius="0.028"/>
            </geometry>
            <origin xyz="0 0 0.013" rpy="0 0 0"/>
        </collision>
        <inertial>
            <mass value="0.003"/>
            <inertia ixx="0.0" ixy="0" ixz="0" iyy="0.0" iyz="0" izz="0.0"/>
            <origin xyz="0 0 0.013" rpy="0 0 0"/>
        </inertial>
    </link>
<!--support_mass_ratio={"joint-trunk-B0L0-to-branch-B1L1P0": 366.667,
 "joint-trunk-B0L0-to-branch-B22L1P0": 366.667,
 "joint-trunk-B0L0-to-branch-B43L1P0": 366.667,
 "joint-trunk-B0L0-to-branch-B64L1P0": 366.667,
 "joint-branch-B1L1P0-to-branch-B2L2P1": 57.667,
 "joint-branch-B1L1P0-to-branch-B7L2P1": 57.667,
 "joint-branch-B1L1P0-to-branch-B12L2P1": 57.667,
 "joint-branch-B1L1P0-to-branch-B17L2P1": 57.667,
 "joint-branch-B22L1P0-to-branch-B23L2P22": 57.667,
 "joint-branch-B22L1P0-to-branch-B28L2P22": 57.667,
 "joint-branch-B22L1P0-to-branch-B33L2P22": 57.667,
 "joint-branch-B22L1P0-to-branch-B38L2P22": 57.667,
 "joint-branch-B43L1P0-to-branch-B44L2P43": 57.667,
 "joint-branch-B43L1P0-to-branch-B49L2P43": 57.667,
 "joint-branch-B43L1P0-to-branch-B54L2P43": 57.667,
 "joint-branch-B43L1P0-to-branch-B59L2P43": 57.667,
 "joint-branch-B64L1P0-to-branch-B65L2P64": 57.667,
 "joint-branch-B64L1P0-to-branch-B70L2P64": 57.667,
 "joint-branch-B64L1P0-to-branch-B75L2P64": 57.667,
 "joint-branch-B64L1P0-to-branch-B80L2P64": 57.667,
 "joint-branch-B2L2P1-to-branch-B3L3P2": 1.0,
 "joint-branch-B2L2P1-to-branch-B4L3P2": 1.0,
 "joint-branch-B2L2P1-to-branch-B5L3P2": 1.0,
 "joint-branch-B2L2P1-to-branch-B6L3P2": 1.0,
 "joint-branch-B7L2P1-to-branch-B8L3P7": 1.0,
 "joint-branch-B7L2P1-to-branch-B9L3P7": 1.0,
 "joint-branch-B7L2P1-to-branch-B10L3P7": 1.0,
 "joint-branch-B7L2P1-to-branch-B11L3P7": 1.0,
 "joint-branch-B12L2P1-to-branch-B13L3P12": 1.0,
 "joint-branch-B12L2P1-to-branch-B14L3P12": 1.0,
 "joint-branch-B12L2P1-to-branch-B15L3P12": 1.0,
 "joint-branch-B12L2P1-to-branch-B16L3P12": 1.0,
 "joint-branch-B17L2P1-to-branch-B18L3P17": 1.0,
 "joint-branch-B17L2P1-to-branch-B19L3P17": 1.0,
 "joint-branch-B17L2P1-to-branch-B20L3P17": 1.0,
 "joint-branch-B17L2P1-to-branch-B21L3P17": 1.0,
 "joint-branch-B23L2P22-to-branch-B24L3P23": 1.0,
 "joint-branch-B23L2P22-to-branch-B25L3P23": 1.0,
 "joint-branch-B23L2P22-to-branch-B26L3P23": 1.0,
 "joint-branch-B23L2P22-to-branch-B27L3P23": 1.0,
 "joint-branch-B28L2P22-to-branch-B29L3P28": 1.0,
 "joint-branch-B28L2P22-to-branch-B30L3P28": 1.0,
 "joint-branch-B28L2P22-to-branch-B31L3P28": 1.0,
 "joint-branch-B28L2P22-to-branch-B32L3P28": 1.0,
 "joint-branch-B33L2P22-to-branch-B34L3P33": 1.0,
 "joint-branch-B33L2P22-to-branch-B35L3P33": 1.0,
 "joint-branch-B33L2P22-to-branch-B36L3P33": 1.0,
 "joint-branch-B33L2P22-to-branch-B37L3P33": 1.0,
 "joint-branch-B38L2P22-to-branch-B39L3P38": 1.0,
 "joint-branch-B38L2P22-to-branch-B40L3P38": 1.0,
 "joint-branch-B38L2P22-to-branch-B41L3P38": 1.0,
 "joint-branch-B38L2P22-to-branch-B42L3P38": 1.0,
 "joint-branch-B44L2P43-to-branch-B45L3P44": 1.0,
 "joint-branch-B44L2P43-to-branch-B46L3P44": 1.0,
 "joint-branch-B44L2P43-to-branch-B47L3P44": 1.0,
 "joint-branch-B44L2P43-to-branch-B48L3P44": 1.0,
 "joint-branch-B49L2P43-to-branch-B50L3P49": 1.0,
 "joint-branch-B49L2P43-to-branch-B51L3P49": 1.0,
 "joint-branch-B49L2P43-to-branch-B52L3P49": 1.0,
 "joint-branch-B49L2P43-to-branch-B53L3P49": 1.0,
 "joint-branch-B54L2P43-to-branch-B55L3P54": 1.0,
 "joint-branch-B54L2P43-to-branch-B56L3P54": 1.0,
 "joint-branch-B54L2P43-to-branch-B57L3P54": 1.0,
 "joint-branch-B54L2P43-to-branch-B58L3P54": 1.0,
 "joint-branch-B59L2P43-to-branch-B60L3P59": 1.0,
 "joint-branch-B59L2P43-to-branch-B61L3P59": 1.0,
 "joint-branch-B59L2P43-to-branch-B62L3P59": 1.0,
 "joint-branch-B59L2P43-to-branch-B63L3P59": 1.0,
 "joint-branch-B65L2P64-to-branch-B66L3P65": 1.0,
 "joint-branch-B65L2P64-to-branch-B67L3P65": 1.0,
 "joint-branch-B65L2P64-to-branch-B68L3P65": 1.0,
 "joint-branch-B65L2P64-to-branch-B69L3P65": 1.0,
 "joint-branch-B70L2P64-to-branch-B71L3P70": 1.0,
 "joint-branch-B70L2P64-to-branch-B72L3P70": 1.0,
 "joint-branch-B70L2P64-to-branch-B73L3P70": 1.0,
 "joint-branch-B70L2P64-to-branch-B74L3P70": 1.0,
 "joint-branch-B75L2P64-to-branch-B76L3P75": 1.0,
 "joint-branch-B75L2P64-to-branch-B77L3P75": 1.0,
 "joint-branch-B75L2P64-to-branch-B78L3P75": 1.0,
 "joint-branch-B75L2P64-to-branch-B79L3P75": 1.0,
 "joint-branch-B80L2P64-to-branch-B81L3P80": 1.0,
 "joint-branch-B80L2P64-to-branch-B82L3P80": 1.0,
 "joint-branch-B80L2P64-to-branch-B83L3P80": 1.0,
 "joint-branch-B80L2P64-to-branch-B84L3P80": 1.0}-->
<!--min_leaf_force=0.033-->
</robot>