<robot name="gt_fixed_parent">
    <link name="world"/>
    <!-- Joint & Link: trunk-B0L0 Branch Id:0 Level: 0, Child idx:0 )-->
<joint name="joint-world-trunk-B0L0" type="fixed">
        <parent link="world"/>
        <child link="link-trunk-B0L0"/>
        <origin xyz="0 0 0" rpy="0 0 0"/>
        </joint>
    <link name="link-trunk-B0L0">
        <visual>
            <geometry>
                <cylinder length="1.5" radius="0.1"/>
            </geometry>
            <origin xyz="0 0 0.75" rpy="0 0 0"/>
            <material name="brown">
                <color rgba="0.1 0.2 0.2 1"/>
            </material>
        </visual>
        <collision>
            <geometry>
                <cylinder length="1.5" radius="0.1"/>
            </geometry>
            <origin xyz="0 0 0.75" rpy="0 0 0"/>
        </collision>
        <inertial>
            <mass value="9.425"/>
            <inertia ixx="0" ixy="0" ixz="0" iyy="0" iyz="0" izz="0"/>
            <origin xyz="0 0 0.75" rpy="0 0 0"/>
        </inertial>
    </link>
<!-- Joint & Link: branch-B1L1P0 Branch Id:1 Level: 1, Child idx:0 )-->
<joint name="joint-trunk-B0L0-to-branch-B1L1P0" type="revolute">
        <parent link="link-trunk-B0L0"/>
        <child link="link-branch-B1L1P0"/>
        <origin xyz="0 0 1.4" rpy="-1.047 0.0 0"/>
        <axis xyz="-1 0 0"/>
        <limit lower="-0.349" upper="0.349"/>
        <dynamics damping="13.108" friction="13.108"/>
    </joint>
    <link name="link-branch-B1L1P0">
        <visual>
            <geometry>
                <cylinder length="0.8" radius="0.071"/>
            </geometry>
            <origin xyz="0 0 0.4" rpy="0 0 0"/>
            <material name="brown">
                <color rgba="0.1 0.2 0.2 1"/>
            </material>
        </visual>
        <collision>
            <geometry>
                <cylinder length="0.8" radius="0.071"/>
            </geometry>
            <origin xyz="0 0 0.4" rpy="0 0 0"/>
        </collision>
        <inertial>
            <mass value="2.534"/>
            <inertia ixx="0.138" ixy="0" ixz="0" iyy="0.138" iyz="0" izz="0.006"/>
            <origin xyz="0 0 0.4" rpy="0 0 0"/>
        </inertial>
    </link>
<!-- Joint & Link: branch-B6L1P0 Branch Id:6 Level: 1, Child idx:1 )-->
<joint name="joint-trunk-B0L0-to-branch-B6L1P0" type="revolute">
        <parent link="link-trunk-B0L0"/>
        <child link="link-branch-B6L1P0"/>
        <origin xyz="0 0 1.4" rpy="1.047 0.0 0"/>
        <axis xyz="1 0 0"/>
        <limit lower="-0.349" upper="0.349"/>
        <dynamics damping="13.108" friction="13.108"/>
    </joint>
    <link name="link-branch-B6L1P0">
        <visual>
            <geometry>
                <cylinder length="0.8" radius="0.071"/>
            </geometry>
            <origin xyz="0 0 0.4" rpy="0 0 0"/>
            <material name="brown">
                <color rgba="0.1 0.2 0.2 1"/>
            </material>
        </visual>
        <collision>
            <geometry>
                <cylinder length="0.8" radius="0.071"/>
            </geometry>
            <origin xyz="0 0 0.4" rpy="0 0 0"/>
        </collision>
        <inertial>
            <mass value="2.534"/>
            <inertia ixx="0.138" ixy="0" ixz="0" iyy="0.138" iyz="0" izz="0.006"/>
            <origin xyz="0 0 0.4" rpy="0 0 0"/>
        </inertial>
    </link>
<!-- Joint & Link: branch-B11L1P0 Branch Id:11 Level: 1, Child idx:2 )-->
<joint name="joint-trunk-B0L0-to-branch-B11L1P0" type="revolute">
        <parent link="link-trunk-B0L0"/>
        <child link="link-branch-B11L1P0"/>
        <origin xyz="0 0 1.4" rpy="0.0 -1.047 0"/>
        <axis xyz="0 -1 0"/>
        <limit lower="-0.349" upper="0.349"/>
        <dynamics damping="13.108" friction="13.108"/>
    </joint>
    <link name="link-branch-B11L1P0">
        <visual>
            <geometry>
                <cylinder length="0.8" radius="0.071"/>
            </geometry>
            <origin xyz="0 0 0.4" rpy="0 0 0"/>
            <material name="brown">
                <color rgba="0.1 0.2 0.2 1"/>
            </material>
        </visual>
        <collision>
            <geometry>
                <cylinder length="0.8" radius="0.071"/>
            </geometry>
            <origin xyz="0 0 0.4" rpy="0 0 0"/>
        </collision>
        <inertial>
            <mass value="2.534"/>
            <inertia ixx="0.138" ixy="0" ixz="0" iyy="0.138" iyz="0" izz="0.006"/>
            <origin xyz="0 0 0.4" rpy="0 0 0"/>
        </inertial>
    </link>
<!-- Joint & Link: branch-B16L1P0 Branch Id:16 Level: 1, Child idx:3 )-->
<joint name="joint-trunk-B0L0-to-branch-B16L1P0" type="fixed">
        <parent link="link-trunk-B0L0"/>
        <child link="link-branch-B16L1P0"/>
        <origin xyz="0 0 1.4" rpy="0.0 1.047 0"/>
        <!-- Fixing the parent for experiments.-->
        <!-- <axis xyz="0 1 0"/>
        <limit lower="-0.349" upper="0.349"/>
        <dynamics damping="13.108" friction="13.108"/>-->
    </joint>
    <link name="link-branch-B16L1P0">
        <visual>
            <geometry>
                <cylinder length="0.8" radius="0.071"/>
            </geometry>
            <origin xyz="0 0 0.4" rpy="0 0 0"/>
            <material name="brown">
                <color rgba="0.1 0.2 0.2 1"/>
            </material>
        </visual>
        <collision>
            <geometry>
                <cylinder length="0.8" radius="0.071"/>
            </geometry>
            <origin xyz="0 0 0.4" rpy="0 0 0"/>
        </collision>
        <inertial>
            <mass value="2.534"/>
            <inertia ixx="0.138" ixy="0" ixz="0" iyy="0.138" iyz="0" izz="0.006"/>
            <origin xyz="0 0 0.4" rpy="0 0 0"/>
        </inertial>
    </link>
<!-- Joint & Link: branch-B2L2P1 Branch Id:2 Level: 2, Child idx:0 )-->
<joint name="joint-branch-B1L1P0-to-branch-B2L2P1" type="revolute">
        <parent link="link-branch-B1L1P0"/>
        <child link="link-branch-B2L2P1"/>
        <origin xyz="0 0 0.7" rpy="-1.047 0.0 0"/>
        <axis xyz="-1 0 0"/>
        <limit lower="-0.349" upper="0.349"/>
        <dynamics damping="2.01" friction="2.01"/>
    </joint>
    <link name="link-branch-B2L2P1">
        <visual>
            <geometry>
                <cylinder length="0.64" radius="0.05"/>
            </geometry>
            <origin xyz="0 0 0.32" rpy="0 0 0"/>
            <material name="green">
                <color rgba="0.1 1 0.2 1"/>
            </material>
        </visual>
        <collision>
            <geometry>
                <cylinder length="0.64" radius="0.05"/>
            </geometry>
            <origin xyz="0 0 0.32" rpy="0 0 0"/>
        </collision>
        <inertial>
            <mass value="1.005"/>
            <inertia ixx="0.035" ixy="0" ixz="0" iyy="0.035" iyz="0" izz="0.001"/>
            <origin xyz="0 0 0.32" rpy="0 0 0"/>
        </inertial>
    </link>
<!-- Joint & Link: branch-B3L2P1 Branch Id:3 Level: 2, Child idx:1 )-->
<joint name="joint-branch-B1L1P0-to-branch-B3L2P1" type="revolute">
        <parent link="link-branch-B1L1P0"/>
        <child link="link-branch-B3L2P1"/>
        <origin xyz="0 0 0.7" rpy="1.047 0.0 0"/>
        <axis xyz="1 0 0"/>
        <limit lower="-0.349" upper="0.349"/>
        <dynamics damping="2.01" friction="2.01"/>
    </joint>
    <link name="link-branch-B3L2P1">
        <visual>
            <geometry>
                <cylinder length="0.64" radius="0.05"/>
            </geometry>
            <origin xyz="0 0 0.32" rpy="0 0 0"/>
            <material name="green">
                <color rgba="0.1 1 0.2 1"/>
            </material>
        </visual>
        <collision>
            <geometry>
                <cylinder length="0.64" radius="0.05"/>
            </geometry>
            <origin xyz="0 0 0.32" rpy="0 0 0"/>
        </collision>
        <inertial>
            <mass value="1.005"/>
            <inertia ixx="0.035" ixy="0" ixz="0" iyy="0.035" iyz="0" izz="0.001"/>
            <origin xyz="0 0 0.32" rpy="0 0 0"/>
        </inertial>
    </link>
<!-- Joint & Link: branch-B4L2P1 Branch Id:4 Level: 2, Child idx:2 )-->
<joint name="joint-branch-B1L1P0-to-branch-B4L2P1" type="revolute">
        <parent link="link-branch-B1L1P0"/>
        <child link="link-branch-B4L2P1"/>
        <origin xyz="0 0 0.7" rpy="0.0 -1.047 0"/>
        <axis xyz="0 -1 0"/>
        <limit lower="-0.349" upper="0.349"/>
        <dynamics damping="2.01" friction="2.01"/>
    </joint>
    <link name="link-branch-B4L2P1">
        <visual>
            <geometry>
                <cylinder length="0.64" radius="0.05"/>
            </geometry>
            <origin xyz="0 0 0.32" rpy="0 0 0"/>
            <material name="green">
                <color rgba="0.1 1 0.2 1"/>
            </material>
        </visual>
        <collision>
            <geometry>
                <cylinder length="0.64" radius="0.05"/>
            </geometry>
            <origin xyz="0 0 0.32" rpy="0 0 0"/>
        </collision>
        <inertial>
            <mass value="1.005"/>
            <inertia ixx="0.035" ixy="0" ixz="0" iyy="0.035" iyz="0" izz="0.001"/>
            <origin xyz="0 0 0.32" rpy="0 0 0"/>
        </inertial>
    </link>
<!-- Joint & Link: branch-B5L2P1 Branch Id:5 Level: 2, Child idx:3 )-->
<joint name="joint-branch-B1L1P0-to-branch-B5L2P1" type="revolute">
        <parent link="link-branch-B1L1P0"/>
        <child link="link-branch-B5L2P1"/>
        <origin xyz="0 0 0.7" rpy="0.0 1.047 0"/>
        <axis xyz="0 1 0"/>
        <limit lower="-0.349" upper="0.349"/>
        <dynamics damping="2.01" friction="2.01"/>
    </joint>
    <link name="link-branch-B5L2P1">
        <visual>
            <geometry>
                <cylinder length="0.64" radius="0.05"/>
            </geometry>
            <origin xyz="0 0 0.32" rpy="0 0 0"/>
            <material name="green">
                <color rgba="0.1 1 0.2 1"/>
            </material>
        </visual>
        <collision>
            <geometry>
                <cylinder length="0.64" radius="0.05"/>
            </geometry>
            <origin xyz="0 0 0.32" rpy="0 0 0"/>
        </collision>
        <inertial>
            <mass value="1.005"/>
            <inertia ixx="0.035" ixy="0" ixz="0" iyy="0.035" iyz="0" izz="0.001"/>
            <origin xyz="0 0 0.32" rpy="0 0 0"/>
        </inertial>
    </link>
<!-- Joint & Link: branch-B7L2P6 Branch Id:7 Level: 2, Child idx:0 )-->
<joint name="joint-branch-B6L1P0-to-branch-B7L2P6" type="revolute">
        <parent link="link-branch-B6L1P0"/>
        <child link="link-branch-B7L2P6"/>
        <origin xyz="0 0 0.7" rpy="-1.047 0.0 0"/>
        <axis xyz="-1 0 0"/>
        <limit lower="-0.349" upper="0.349"/>
        <dynamics damping="2.01" friction="2.01"/>
    </joint>
    <link name="link-branch-B7L2P6">
        <visual>
            <geometry>
                <cylinder length="0.64" radius="0.05"/>
            </geometry>
            <origin xyz="0 0 0.32" rpy="0 0 0"/>
            <material name="green">
                <color rgba="0.1 1 0.2 1"/>
            </material>
        </visual>
        <collision>
            <geometry>
                <cylinder length="0.64" radius="0.05"/>
            </geometry>
            <origin xyz="0 0 0.32" rpy="0 0 0"/>
        </collision>
        <inertial>
            <mass value="1.005"/>
            <inertia ixx="0.035" ixy="0" ixz="0" iyy="0.035" iyz="0" izz="0.001"/>
            <origin xyz="0 0 0.32" rpy="0 0 0"/>
        </inertial>
    </link>
<!-- Joint & Link: branch-B8L2P6 Branch Id:8 Level: 2, Child idx:1 )-->
<joint name="joint-branch-B6L1P0-to-branch-B8L2P6" type="revolute">
        <parent link="link-branch-B6L1P0"/>
        <child link="link-branch-B8L2P6"/>
        <origin xyz="0 0 0.7" rpy="1.047 0.0 0"/>
        <axis xyz="1 0 0"/>
        <limit lower="-0.349" upper="0.349"/>
        <dynamics damping="2.01" friction="2.01"/>
    </joint>
    <link name="link-branch-B8L2P6">
        <visual>
            <geometry>
                <cylinder length="0.64" radius="0.05"/>
            </geometry>
            <origin xyz="0 0 0.32" rpy="0 0 0"/>
            <material name="green">
                <color rgba="0.1 1 0.2 1"/>
            </material>
        </visual>
        <collision>
            <geometry>
                <cylinder length="0.64" radius="0.05"/>
            </geometry>
            <origin xyz="0 0 0.32" rpy="0 0 0"/>
        </collision>
        <inertial>
            <mass value="1.005"/>
            <inertia ixx="0.035" ixy="0" ixz="0" iyy="0.035" iyz="0" izz="0.001"/>
            <origin xyz="0 0 0.32" rpy="0 0 0"/>
        </inertial>
    </link>
<!-- Joint & Link: branch-B9L2P6 Branch Id:9 Level: 2, Child idx:2 )-->
<joint name="joint-branch-B6L1P0-to-branch-B9L2P6" type="revolute">
        <parent link="link-branch-B6L1P0"/>
        <child link="link-branch-B9L2P6"/>
        <origin xyz="0 0 0.7" rpy="0.0 -1.047 0"/>
        <axis xyz="0 -1 0"/>
        <limit lower="-0.349" upper="0.349"/>
        <dynamics damping="2.01" friction="2.01"/>
    </joint>
    <link name="link-branch-B9L2P6">
        <visual>
            <geometry>
                <cylinder length="0.64" radius="0.05"/>
            </geometry>
            <origin xyz="0 0 0.32" rpy="0 0 0"/>
            <material name="green">
                <color rgba="0.1 1 0.2 1"/>
            </material>
        </visual>
        <collision>
            <geometry>
                <cylinder length="0.64" radius="0.05"/>
            </geometry>
            <origin xyz="0 0 0.32" rpy="0 0 0"/>
        </collision>
        <inertial>
            <mass value="1.005"/>
            <inertia ixx="0.035" ixy="0" ixz="0" iyy="0.035" iyz="0" izz="0.001"/>
            <origin xyz="0 0 0.32" rpy="0 0 0"/>
        </inertial>
    </link>
<!-- Joint & Link: branch-B10L2P6 Branch Id:10 Level: 2, Child idx:3 )-->
<joint name="joint-branch-B6L1P0-to-branch-B10L2P6" type="revolute">
        <parent link="link-branch-B6L1P0"/>
        <child link="link-branch-B10L2P6"/>
        <origin xyz="0 0 0.7" rpy="0.0 1.047 0"/>
        <axis xyz="0 1 0"/>
        <limit lower="-0.349" upper="0.349"/>
        <dynamics damping="2.01" friction="2.01"/>
    </joint>
    <link name="link-branch-B10L2P6">
        <visual>
            <geometry>
                <cylinder length="0.64" radius="0.05"/>
            </geometry>
            <origin xyz="0 0 0.32" rpy="0 0 0"/>
            <material name="green">
                <color rgba="0.1 1 0.2 1"/>
            </material>
        </visual>
        <collision>
            <geometry>
                <cylinder length="0.64" radius="0.05"/>
            </geometry>
            <origin xyz="0 0 0.32" rpy="0 0 0"/>
        </collision>
        <inertial>
            <mass value="1.005"/>
            <inertia ixx="0.035" ixy="0" ixz="0" iyy="0.035" iyz="0" izz="0.001"/>
            <origin xyz="0 0 0.32" rpy="0 0 0"/>
        </inertial>
    </link>
<!-- Joint & Link: branch-B12L2P11 Branch Id:12 Level: 2, Child idx:0 )-->
<joint name="joint-branch-B11L1P0-to-branch-B12L2P11" type="revolute">
        <parent link="link-branch-B11L1P0"/>
        <child link="link-branch-B12L2P11"/>
        <origin xyz="0 0 0.7" rpy="-1.047 0.0 0"/>
        <axis xyz="-1 0 0"/>
        <limit lower="-0.349" upper="0.349"/>
        <dynamics damping="2.01" friction="2.01"/>
    </joint>
    <link name="link-branch-B12L2P11">
        <visual>
            <geometry>
                <cylinder length="0.64" radius="0.05"/>
            </geometry>
            <origin xyz="0 0 0.32" rpy="0 0 0"/>
            <material name="green">
                <color rgba="0.1 1 0.2 1"/>
            </material>
        </visual>
        <collision>
            <geometry>
                <cylinder length="0.64" radius="0.05"/>
            </geometry>
            <origin xyz="0 0 0.32" rpy="0 0 0"/>
        </collision>
        <inertial>
            <mass value="1.005"/>
            <inertia ixx="0.035" ixy="0" ixz="0" iyy="0.035" iyz="0" izz="0.001"/>
            <origin xyz="0 0 0.32" rpy="0 0 0"/>
        </inertial>
    </link>
<!-- Joint & Link: branch-B13L2P11 Branch Id:13 Level: 2, Child idx:1 )-->
<joint name="joint-branch-B11L1P0-to-branch-B13L2P11" type="revolute">
        <parent link="link-branch-B11L1P0"/>
        <child link="link-branch-B13L2P11"/>
        <origin xyz="0 0 0.7" rpy="1.047 0.0 0"/>
        <axis xyz="1 0 0"/>
        <limit lower="-0.349" upper="0.349"/>
        <dynamics damping="2.01" friction="2.01"/>
    </joint>
    <link name="link-branch-B13L2P11">
        <visual>
            <geometry>
                <cylinder length="0.64" radius="0.05"/>
            </geometry>
            <origin xyz="0 0 0.32" rpy="0 0 0"/>
            <material name="green">
                <color rgba="0.1 1 0.2 1"/>
            </material>
        </visual>
        <collision>
            <geometry>
                <cylinder length="0.64" radius="0.05"/>
            </geometry>
            <origin xyz="0 0 0.32" rpy="0 0 0"/>
        </collision>
        <inertial>
            <mass value="1.005"/>
            <inertia ixx="0.035" ixy="0" ixz="0" iyy="0.035" iyz="0" izz="0.001"/>
            <origin xyz="0 0 0.32" rpy="0 0 0"/>
        </inertial>
    </link>
<!-- Joint & Link: branch-B14L2P11 Branch Id:14 Level: 2, Child idx:2 )-->
<joint name="joint-branch-B11L1P0-to-branch-B14L2P11" type="revolute">
        <parent link="link-branch-B11L1P0"/>
        <child link="link-branch-B14L2P11"/>
        <origin xyz="0 0 0.7" rpy="0.0 -1.047 0"/>
        <axis xyz="0 -1 0"/>
        <limit lower="-0.349" upper="0.349"/>
        <dynamics damping="2.01" friction="2.01"/>
    </joint>
    <link name="link-branch-B14L2P11">
        <visual>
            <geometry>
                <cylinder length="0.64" radius="0.05"/>
            </geometry>
            <origin xyz="0 0 0.32" rpy="0 0 0"/>
            <material name="green">
                <color rgba="0.1 1 0.2 1"/>
            </material>
        </visual>
        <collision>
            <geometry>
                <cylinder length="0.64" radius="0.05"/>
            </geometry>
            <origin xyz="0 0 0.32" rpy="0 0 0"/>
        </collision>
        <inertial>
            <mass value="1.005"/>
            <inertia ixx="0.035" ixy="0" ixz="0" iyy="0.035" iyz="0" izz="0.001"/>
            <origin xyz="0 0 0.32" rpy="0 0 0"/>
        </inertial>
    </link>
<!-- Joint & Link: branch-B15L2P11 Branch Id:15 Level: 2, Child idx:3 )-->
<joint name="joint-branch-B11L1P0-to-branch-B15L2P11" type="revolute">
        <parent link="link-branch-B11L1P0"/>
        <child link="link-branch-B15L2P11"/>
        <origin xyz="0 0 0.7" rpy="0.0 1.047 0"/>
        <axis xyz="0 1 0"/>
        <limit lower="-0.349" upper="0.349"/>
        <dynamics damping="2.01" friction="2.01"/>
    </joint>
    <link name="link-branch-B15L2P11">
        <visual>
            <geometry>
                <cylinder length="0.64" radius="0.05"/>
            </geometry>
            <origin xyz="0 0 0.32" rpy="0 0 0"/>
            <material name="green">
                <color rgba="0.1 1 0.2 1"/>
            </material>
        </visual>
        <collision>
            <geometry>
                <cylinder length="0.64" radius="0.05"/>
            </geometry>
            <origin xyz="0 0 0.32" rpy="0 0 0"/>
        </collision>
        <inertial>
            <mass value="1.005"/>
            <inertia ixx="0.035" ixy="0" ixz="0" iyy="0.035" iyz="0" izz="0.001"/>
            <origin xyz="0 0 0.32" rpy="0 0 0"/>
        </inertial>
    </link>
<!-- Joint & Link: branch-B17L2P16 Branch Id:17 Level: 2, Child idx:0 )-->
<joint name="joint-branch-B16L1P0-to-branch-B17L2P16" type="revolute">
        <parent link="link-branch-B16L1P0"/>
        <child link="link-branch-B17L2P16"/>
        <origin xyz="0 0 0.7" rpy="-1.047 0.0 0"/>
        <axis xyz="-1 0 0"/>
        <limit lower="-0.349" upper="0.349"/>
        <dynamics damping="2.01" friction="2.01"/>
    </joint>
    <link name="link-branch-B17L2P16">
        <visual>
            <geometry>
                <cylinder length="0.64" radius="0.05"/>
            </geometry>
            <origin xyz="0 0 0.32" rpy="0 0 0"/>
            <material name="green">
                <color rgba="0.1 1 0.2 1"/>
            </material>
        </visual>
        <collision>
            <geometry>
                <cylinder length="0.64" radius="0.05"/>
            </geometry>
            <origin xyz="0 0 0.32" rpy="0 0 0"/>
        </collision>
        <inertial>
            <mass value="1.005"/>
            <inertia ixx="0.035" ixy="0" ixz="0" iyy="0.035" iyz="0" izz="0.001"/>
            <origin xyz="0 0 0.32" rpy="0 0 0"/>
        </inertial>
    </link>
<!-- Joint & Link: branch-B18L2P16 Branch Id:18 Level: 2, Child idx:1 )-->
<joint name="joint-branch-B16L1P0-to-branch-B18L2P16" type="revolute">
        <parent link="link-branch-B16L1P0"/>
        <child link="link-branch-B18L2P16"/>
        <origin xyz="0 0 0.7" rpy="1.047 0.0 0"/>
        <axis xyz="1 0 0"/>
        <limit lower="-0.349" upper="0.349"/>
        <dynamics damping="2.01" friction="2.01"/>
    </joint>
    <link name="link-branch-B18L2P16">
        <visual>
            <geometry>
                <cylinder length="0.64" radius="0.05"/>
            </geometry>
            <origin xyz="0 0 0.32" rpy="0 0 0"/>
            <material name="green">
                <color rgba="0.1 1 0.2 1"/>
            </material>
        </visual>
        <collision>
            <geometry>
                <cylinder length="0.64" radius="0.05"/>
            </geometry>
            <origin xyz="0 0 0.32" rpy="0 0 0"/>
        </collision>
        <inertial>
            <mass value="1.005"/>
            <inertia ixx="0.035" ixy="0" ixz="0" iyy="0.035" iyz="0" izz="0.001"/>
            <origin xyz="0 0 0.32" rpy="0 0 0"/>
        </inertial>
    </link>
<!-- Joint & Link: branch-B19L2P16 Branch Id:19 Level: 2, Child idx:2 )-->
<joint name="joint-branch-B16L1P0-to-branch-B19L2P16" type="revolute">
        <parent link="link-branch-B16L1P0"/>
        <child link="link-branch-B19L2P16"/>
        <origin xyz="0 0 0.7" rpy="0.0 -1.047 0"/>
        <axis xyz="0 -1 0"/>
        <limit lower="-0.349" upper="0.349"/>
        <dynamics damping="2.01" friction="2.01"/>
    </joint>
    <link name="link-branch-B19L2P16">
        <visual>
            <geometry>
                <cylinder length="0.64" radius="0.05"/>
            </geometry>
            <origin xyz="0 0 0.32" rpy="0 0 0"/>
            <material name="green">
                <color rgba="0.1 1 0.2 1"/>
            </material>
        </visual>
        <collision>
            <geometry>
                <cylinder length="0.64" radius="0.05"/>
            </geometry>
            <origin xyz="0 0 0.32" rpy="0 0 0"/>
        </collision>
        <inertial>
            <mass value="1.005"/>
            <inertia ixx="0.035" ixy="0" ixz="0" iyy="0.035" iyz="0" izz="0.001"/>
            <origin xyz="0 0 0.32" rpy="0 0 0"/>
        </inertial>
    </link>
<!-- Joint & Link: branch-B20L2P16 Branch Id:20 Level: 2, Child idx:3 )-->
<joint name="joint-branch-B16L1P0-to-branch-B20L2P16" type="revolute">
        <parent link="link-branch-B16L1P0"/>
        <child link="link-branch-B20L2P16"/>
        <origin xyz="0 0 0.7" rpy="0.0 1.047 0"/>
        <axis xyz="0 1 0"/>
        <limit lower="-0.349" upper="0.349"/>
        <dynamics damping="2.01" friction="2.01"/>
    </joint>
    <link name="link-branch-B20L2P16">
        <visual>
            <geometry>
                <cylinder length="0.64" radius="0.05"/>
            </geometry>
            <origin xyz="0 0 0.32" rpy="0 0 0"/>
            <material name="red">
                <color rgba="1 0.1 0.2 1"/>
            </material>
        </visual>
        <collision>
            <geometry>
                <cylinder length="0.64" radius="0.05"/>
            </geometry>
            <origin xyz="0 0 0.32" rpy="0 0 0"/>
        </collision>
        <inertial>
            <mass value="1.005"/>
            <inertia ixx="0.035" ixy="0" ixz="0" iyy="0.035" iyz="0" izz="0.001"/>
            <origin xyz="0 0 0.32" rpy="0 0 0"/>
        </inertial>
    </link>
<!--support_mass_ratio={"joint-trunk-B0L0-to-branch-B1L1P0": 6.521,
 "joint-trunk-B0L0-to-branch-B6L1P0": 6.521,
 "joint-trunk-B0L0-to-branch-B11L1P0": 6.521,
 "joint-trunk-B0L0-to-branch-B16L1P0": 6.521,
 "joint-branch-B1L1P0-to-branch-B2L2P1": 1.0,
 "joint-branch-B1L1P0-to-branch-B3L2P1": 1.0,
 "joint-branch-B1L1P0-to-branch-B4L2P1": 1.0,
 "joint-branch-B1L1P0-to-branch-B5L2P1": 1.0,
 "joint-branch-B6L1P0-to-branch-B7L2P6": 1.0,
 "joint-branch-B6L1P0-to-branch-B8L2P6": 1.0,
 "joint-branch-B6L1P0-to-branch-B9L2P6": 1.0,
 "joint-branch-B6L1P0-to-branch-B10L2P6": 1.0,
 "joint-branch-B11L1P0-to-branch-B12L2P11": 1.0,
 "joint-branch-B11L1P0-to-branch-B13L2P11": 1.0,
 "joint-branch-B11L1P0-to-branch-B14L2P11": 1.0,
 "joint-branch-B11L1P0-to-branch-B15L2P11": 1.0,
 "joint-branch-B16L1P0-to-branch-B17L2P16": 1.0,
 "joint-branch-B16L1P0-to-branch-B18L2P16": 1.0,
 "joint-branch-B16L1P0-to-branch-B19L2P16": 1.0,
 "joint-branch-B16L1P0-to-branch-B20L2P16": 1.0}-->
<!--min_leaf_force=14.069999999999999-->
</robot>